Workbook
Name imp: #REF!
Name imp: #REF!
Name imp: #REF!
Name imp: #REF!
Name imp: #REF!
Name imp: #REF!
Name imp: #REF!
Name imp: #REF!
Name imp: #REF!
Name imp: #REF!
Name imp: #REF!
Name imp: #REF!
Name imp: #REF!
Name imp: #REF!
Name imp: #REF!
Name imp: #REF!
Name imp: #REF!
Name imp: #REF!
Name imp: #REF!
Name imp: #REF!
Name imp: #REF!
Name imp: #REF!
Name imp: #REF!
Name imp: #REF!
Name imp: #REF!
Name impa: #REF!
Name impa: #REF!
Name impa: #REF!
Name impa: #REF!
Name impa: #REF!
Name impa: #REF!
Name impa: #REF!
Name impa: #REF!
Name impa: #REF!
Name impa: #REF!
Name impa: #REF!
Name impa: #REF!
Name impa: #REF!
Name impa: #REF!
Name impa: #REF!
Name impa: #REF!
Name impa: #REF!
Name impa: #REF!
Name impa: #REF!
Name impa: #REF!
Name impa: #REF!
Name impa: #REF!
Name impa: #REF!
Name impa: #REF!
Name impactors: #REF!
Name impactors: #REF!
Name impactors: #REF!
Name impactors: #REF!
Name impactors: #REF!
Name impactors: #REF!
Name impactors: #REF!
Name impactors: #REF!
Name impactors: #REF!
Name impactors: #REF!
Name impactors: #REF!

Sheet DBP
B1: SAME Combined Results | N1: Smoke Generation | V1: Primary Diagnostics | AI1: Secondary Diagnostics Volume
A2: Flight 1=same 2=sameR, g=ground | B2: Carousel | C2: Sample Type | D2: Sample ID | E2: Test ID Number | F2: Position in Carousel | G2: SAME # | H2: Description | I2: GMT | J2: Date (EST) | K2: TEAM Test ID Number | L2: Fan problem | M2: Flat profiles | N2: Inlet Velocity (cm/sec) | O2: Rt/R0 | P2: Duration (sec) | Q2: Primary Aging Duration (sec) | R2: Primary Mixing Duration (sec) | S2: PreAge Thermal Precipitator | T2: PreAge Thermal Precipitator Duration | U2: Net Aging Duration | V2: Primary Aging Therm Precip | W2: Primary Aging Therm Precip Duration | X2: Use STS Detector | Y2: Use Comm Diag A | Z2: Use Comm Diag B | AA2: Diluting A | AB2: Diluting B | AC2: Impactor Inlet on CDA | AD2: Cyclone Inlet on CDA (MPASS) | AE2: Impactor Inlet on CDB | AF2: Use P-Trak | AG2: Aerosol Concentration To P-Trak | AH2: Aerosol Conteration to DustTrak | AI2: Secondary Diagnostics Volume % | AJ2: Secondary Aging Duration (sec) | AK2: Secondary Mixing Duration (sec) | AL2: STSDetector | AM2: Comm Diag A | AN2: Comm Diag B | AO2: Diluting A | AP2: Diluting B | AQ2: Ues PTrak | AR2: Aerosol Concentration To P-Trak | AS2: Aerosol Conteration to DustTrak | AT2: secondary agign thermal precip duration | AU2: Mass Loss | AV2: ISS Obscuration (volts) | AW2: ISS Detector Scatter (volts) | AX2: STS Detector (volts) | AY2: STS Detector offset (volts) | AZ2: Ion A (volts) | BA2: Ion A offset V0 (volts) | BB2: Ion A (volts) Mpass_3rd | BC2: Ion A offset V0 Mpass (volts) | BD2: Ion B (volts) | BE2: Ion B offset V0 (volts) | BF2: Ptrak (PT/cc) | BG2: DustTrak A (mg/m3) Mpass_2nd | BH2: DustTrak A (mg/m3) Mpass_2nd offset | BI2: DustTrak A (mg/m3) | BJ2: DustTrak B (mg/m3) | BK2: Ion B Delta (volts) | BL2: M0 best Diameter | BM2: M1 (mm/cm^3) | BN2: Mpass_3rd offset and dilution corrected | BO2: DustTrak A (mg/m3) Mpass_2nd offset, dilution and Gain corrected | BP2: DustTrak A calibratred and corrected for dilution (mg/m3) | BQ2: DustTrak B calibratred and corrected for dilution (mg/m3) | BR2: M1/M0 (micro-m)--CMD | BS2: Diameter of Average mass (micro-m) | BT2: MPASS 3/2 | BU2: Hatch Choate Sigma g | BV2: Hatch Choate Dg | BW2: CPC 100 nm cal, dilution corrected | BX2: CPC 600 nm cal, dilution corrected | BY2: CPC 1200 nm cal, dilution corrected | BZ2: Ion B Mment (mm/cm^3) | CA2: Ion B X | CB2: Dust Trak Cal Factor (Teom/Dusttrak) | CC2: Dust Trak Dilution factor | CD2: Particle density g/cc
A3: 1 | B3: ='SAME1 Flight Tests 8-27-09'!A21 -> 2 | C3: ='SAME1 Flight Tests 8-27-09'!B21 -> DBP | E3: ='SAME1 Flight Tests 8-27-09'!C21 -> 18 D | F3: ='SAME1 Flight Tests 8-27-09'!D21 -> 6 | G3: ='SAME1 Flight Tests 8-27-09'!E21 -> 18 | H3: ='SAME1 Flight Tests 8-27-09'!F21 -> Repeat | I3: ='SAME1 Flight Tests 8-27-09'!G21 -> 264 | J3: ='SAME1 Flight Tests 8-27-09'!H21 -> 39346 | K3: ='SAME1 Flight Tests 8-27-09'!I21 -> 0 | L3: ='SAME1 Flight Tests 8-27-09'!J21 -> n | ... R3: ='SAME1 Flight Tests 8-27-09'!P21 -> 40 | U3: ='SAME1 Flight Tests 8-27-09'!Q21 -> 49.666667 | AA3: ='SAME1 Flight Tests 8-27-09'!R21 -> y | AB3: ='SAME1 Flight Tests 8-27-09'!S21 -> y | AC3: ='SAME1 Flight Tests 8-27-09'!T21 -> 1 | AE3: ='SAME1 Flight Tests 8-27-09'!U21 -> 10 | AG3: ='SAME1 Flight Tests 8-27-09'!V21 -> 0.13253466 | AH3: ='SAME1 Flight Tests 8-27-09'!W21 -> 0.37471482 | AU3: ='SAME1 Flight Tests 8-27-09'!X21 -> n/a | AV3: ='SAME1 Flight Tests 8-27-09'!Y21 -> 3.2196505 | AW3: ='SAME1 Flight Tests 8-27-09'!Z21 -> 6.241195 | AX3: ='SAME1 Flight Tests 8-27-09'!AA21 -> -0.000701904 | BA3: ='SAME1 Flight Tests 8-27-09'!AC21 -> 4.8455355 | BD3: ='SAME1 Flight Tests 8-27-09'!AB21 -> 5.058533 | BE3: ='SAME1 Flight Tests 8-27-09'!AD21 -> 4.677444 | BF3: ='SAME1 Flight Tests 8-27-09'!AE21 -> 6168 | BI3: ='SAME1 Flight Tests 8-27-09'!AF21 -> 1.7445 | BJ3: ='SAME1 Flight Tests 8-27-09'!AG21 -> 36.6584 | BK3: ='SAME1 Flight Tests 8-27-09'!AH21 -> 0.381089 | BL3: ='SAME1 Flight Tests 8-27-09'!AK21 -> 0 | BM3: ='SAME1 Flight Tests 8-27-09'!AL21 -> 0 | BQ3: ='SAME1 Flight Tests 8-27-09'!AM21 -> 0 | BR3: ='SAME1 Flight Tests 8-27-09'!AP21 -> 0 | BS3: ='SAME1 Flight Tests 8-27-09'!AQ21 -> 0 | BU3: ='SAME1 Flight Tests 8-27-09'!AS21 -> 0 | BV3: ='SAME1 Flight Tests 8-27-09'!AT21 -> 0 | BW3: ='SAME1 Flight Tests 8-27-09'!BB21 -> 64872.066 | BX3: ='SAME1 Flight Tests 8-27-09'!BC21 -> 63801.674 | BY3: ='SAME1 Flight Tests 8-27-09'!BD21 -> 60736.259 | CA3: ='SAME1 Flight Tests 8-27-09'!BG21 -> 0 | CB3: ='SAME1 Flight Tests 8-27-09'!BF21 -> 0 | CD3: ='SAME1 Flight Tests 8-27-09'!BE21 -> 0
A4: 1 | B4: ='SAME1 Flight Tests 8-27-09'!A22 -> 2 | C4: ='SAME1 Flight Tests 8-27-09'!B22 -> DBP | E4: ='SAME1 Flight Tests 8-27-09'!C22 -> 19 D | F4: ='SAME1 Flight Tests 8-27-09'!D22 -> 6 | G4: ='SAME1 Flight Tests 8-27-09'!E22 -> 19 | H4: ='SAME1 Flight Tests 8-27-09'!F22 -> Repeat | I4: ='SAME1 Flight Tests 8-27-09'!G22 -> 264 | J4: ='SAME1 Flight Tests 8-27-09'!H22 -> 39346 | K4: ='SAME1 Flight Tests 8-27-09'!I22 -> 0 | L4: ='SAME1 Flight Tests 8-27-09'!J22 -> n | ... R4: ='SAME1 Flight Tests 8-27-09'!P22 -> 20 | U4: ='SAME1 Flight Tests 8-27-09'!Q22 -> 94 | AA4: ='SAME1 Flight Tests 8-27-09'!R22 -> y | AB4: ='SAME1 Flight Tests 8-27-09'!S22 -> y | AC4: ='SAME1 Flight Tests 8-27-09'!T22 -> 1 | AE4: ='SAME1 Flight Tests 8-27-09'!U22 -> 10 | AG4: ='SAME1 Flight Tests 8-27-09'!V22 -> 0.13253466 | AH4: ='SAME1 Flight Tests 8-27-09'!W22 -> 0.37581528 | AU4: ='SAME1 Flight Tests 8-27-09'!X22 -> n/a | AV4: ='SAME1 Flight Tests 8-27-09'!Y22 -> 3.1876515 | AW4: ='SAME1 Flight Tests 8-27-09'!Z22 -> 6.2453005 | AX4: ='SAME1 Flight Tests 8-27-09'!AA22 -> -0.00073242175 | BA4: ='SAME1 Flight Tests 8-27-09'!AC22 -> 4.859603 | BD4: ='SAME1 Flight Tests 8-27-09'!AB22 -> 5.003586 | BE4: ='SAME1 Flight Tests 8-27-09'!AD22 -> 4.670167 | BF4: ='SAME1 Flight Tests 8-27-09'!AE22 -> 2106.5 | BI4: ='SAME1 Flight Tests 8-27-09'!AF22 -> 0.40955 | BJ4: ='SAME1 Flight Tests 8-27-09'!AG22 -> 40.71575 | BK4: ='SAME1 Flight Tests 8-27-09'!AH22 -> 0.333419 | BL4: ='SAME1 Flight Tests 8-27-09'!AK22 -> 0 | BM4: ='SAME1 Flight Tests 8-27-09'!AL22 -> 0 | BQ4: ='SAME1 Flight Tests 8-27-09'!AM22 -> 0 | BR4: ='SAME1 Flight Tests 8-27-09'!AP22 -> 0 | BS4: ='SAME1 Flight Tests 8-27-09'!AQ22 -> 0 | BU4: ='SAME1 Flight Tests 8-27-09'!AS22 -> 0 | BV4: ='SAME1 Flight Tests 8-27-09'!AT22 -> 0 | BW4: ='SAME1 Flight Tests 8-27-09'!BB22 -> 22026.05 | BX4: ='SAME1 Flight Tests 8-27-09'!BC22 -> 21660.489 | BY4: ='SAME1 Flight Tests 8-27-09'!BD22 -> 20678.139 | CA4: ='SAME1 Flight Tests 8-27-09'!BG22 -> 0 | CB4: ='SAME1 Flight Tests 8-27-09'!BF22 -> 0 | CD4: ='SAME1 Flight Tests 8-27-09'!BE22 -> 0
A5: 1 | B5: ='SAME1 Flight Tests 8-27-09'!A25 -> 2 | C5: ='SAME1 Flight Tests 8-27-09'!B25 -> DBP | E5: ='SAME1 Flight Tests 8-27-09'!C25 -> 22 D | F5: ='SAME1 Flight Tests 8-27-09'!D25 -> 6 | G5: ='SAME1 Flight Tests 8-27-09'!E25 -> 22 | H5: ='SAME1 Flight Tests 8-27-09'!F25 -> Repeat | I5: ='SAME1 Flight Tests 8-27-09'!G25 -> 264 | J5: ='SAME1 Flight Tests 8-27-09'!H25 -> 39346 | K5: ='SAME1 Flight Tests 8-27-09'!I25 -> 0 | L5: ='SAME1 Flight Tests 8-27-09'!J25 -> n | ... R5: ='SAME1 Flight Tests 8-27-09'!P25 -> 40 | U5: ='SAME1 Flight Tests 8-27-09'!Q25 -> 41 | AA5: ='SAME1 Flight Tests 8-27-09'!R25 -> y | AB5: ='SAME1 Flight Tests 8-27-09'!S25 -> y | AC5: ='SAME1 Flight Tests 8-27-09'!T25 -> 1 | AE5: ='SAME1 Flight Tests 8-27-09'!U25 -> 10 | AG5: ='SAME1 Flight Tests 8-27-09'!V25 -> 0.13253466 | AH5: ='SAME1 Flight Tests 8-27-09'!W25 -> 0.377121 | AU5: ='SAME1 Flight Tests 8-27-09'!X25 -> 14.56 | AV5: ='SAME1 Flight Tests 8-27-09'!Y25 -> 3.2622525 | AW5: ='SAME1 Flight Tests 8-27-09'!Z25 -> 6.2579045 | AX5: ='SAME1 Flight Tests 8-27-09'!AA25 -> -0.00068664535 | BA5: ='SAME1 Flight Tests 8-27-09'!AC25 -> 4.8670553 | BD5: ='SAME1 Flight Tests 8-27-09'!AB25 -> 4.9152215 | BE5: ='SAME1 Flight Tests 8-27-09'!AD25 -> 4.6375326 | BF5: ='SAME1 Flight Tests 8-27-09'!AE25 -> 1106 | BI5: ='SAME1 Flight Tests 8-27-09'!AF25 -> 0.05455 | BJ5: ='SAME1 Flight Tests 8-27-09'!AG25 -> 29.29695 | BK5: ='SAME1 Flight Tests 8-27-09'!AH25 -> 0.27768887 | BL5: ='SAME1 Flight Tests 8-27-09'!AK25 -> 0 | BM5: ='SAME1 Flight Tests 8-27-09'!AL25 -> 0 | BQ5: ='SAME1 Flight Tests 8-27-09'!AM25 -> 0 | BR5: ='SAME1 Flight Tests 8-27-09'!AP25 -> 0 | BS5: ='SAME1 Flight Tests 8-27-09'!AQ25 -> 0 | BU5: ='SAME1 Flight Tests 8-27-09'!AS25 -> 0 | BV5: ='SAME1 Flight Tests 8-27-09'!AT25 -> 0 | BW5: ='SAME1 Flight Tests 8-27-09'!BB25 -> 11547.893 | BX5: ='SAME1 Flight Tests 8-27-09'!BC25 -> 11355.958 | BY5: ='SAME1 Flight Tests 8-27-09'!BD25 -> 10848.533 | CA5: ='SAME1 Flight Tests 8-27-09'!BG25 -> 0 | CB5: ='SAME1 Flight Tests 8-27-09'!BF25 -> 0 | CD5: ='SAME1 Flight Tests 8-27-09'!BE25 -> 0
A6: 1 | B6: ='SAME1 Flight Tests 8-27-09'!A44 -> 5 | C6: ='SAME1 Flight Tests 8-27-09'!B44 -> DBP | E6: ='SAME1 Flight Tests 8-27-09'!C44 -> 36 D | F6: ='SAME1 Flight Tests 8-27-09'!D44 -> 6 | G6: ='SAME1 Flight Tests 8-27-09'!E44 -> 36 | H6: ='SAME1 Flight Tests 8-27-09'!F44 -> baseline | I6: ='SAME1 Flight Tests 8-27-09'!G44 -> 276 | J6: ='SAME1 Flight Tests 8-27-09'!H44 -> 39358 | K6: ='SAME1 Flight Tests 8-27-09'!I44 -> 0 | L6: ='SAME1 Flight Tests 8-27-09'!J44 -> n | ... R6: ='SAME1 Flight Tests 8-27-09'!P44 -> 8 | U6: ='SAME1 Flight Tests 8-27-09'!Q44 -> 50 | AA6: ='SAME1 Flight Tests 8-27-09'!R44 -> y | AB6: ='SAME1 Flight Tests 8-27-09'!S44 -> y | AC6: ='SAME1 Flight Tests 8-27-09'!T44 -> 1 | AE6: ='SAME1 Flight Tests 8-27-09'!U44 -> 10 | AG6: ='SAME1 Flight Tests 8-27-09'!V44 -> 0.13253466 | AH6: ='SAME1 Flight Tests 8-27-09'!W44 -> 0.3703441 | AU6: ='SAME1 Flight Tests 8-27-09'!X44 -> n/a | AV6: ='SAME1 Flight Tests 8-27-09'!Y44 -> 3.0152895 | AW6: ='SAME1 Flight Tests 8-27-09'!Z44 -> 6.2431795 | AX6: ='SAME1 Flight Tests 8-27-09'!AA44 -> -0.0006713866 | BA6: ='SAME1 Flight Tests 8-27-09'!AC44 -> 4.8207255 | BD6: ='SAME1 Flight Tests 8-27-09'!AB44 -> 5.415131 | BE6: ='SAME1 Flight Tests 8-27-09'!AD44 -> 4.6674955 | BF6: ='SAME1 Flight Tests 8-27-09'!AE44 -> 10465 | BI6: ='SAME1 Flight Tests 8-27-09'!AF44 -> 1.82625 | BJ6: ='SAME1 Flight Tests 8-27-09'!AG44 -> 84.9141 | BK6: ='SAME1 Flight Tests 8-27-09'!AH44 -> 0.7476355 | BL6: ='SAME1 Flight Tests 8-27-09'!AK44 -> 0 | BM6: ='SAME1 Flight Tests 8-27-09'!AL44 -> 0 | BQ6: ='SAME1 Flight Tests 8-27-09'!AM44 -> 0 | BR6: ='SAME1 Flight Tests 8-27-09'!AP44 -> 0 | BS6: ='SAME1 Flight Tests 8-27-09'!AQ44 -> 0 | BU6: ='SAME1 Flight Tests 8-27-09'!AS44 -> 0 | BV6: ='SAME1 Flight Tests 8-27-09'!AT44 -> 0 | BW6: ='SAME1 Flight Tests 8-27-09'!BB44 -> 110744.44 | BX6: ='SAME1 Flight Tests 8-27-09'!BC44 -> 108928.35 | BY6: ='SAME1 Flight Tests 8-27-09'!BD44 -> 103388.09 | CA6: ='SAME1 Flight Tests 8-27-09'!BG44 -> 0 | CB6: ='SAME1 Flight Tests 8-27-09'!BF44 -> 0 | CD6: ='SAME1 Flight Tests 8-27-09'!BE44 -> 0
A7: 1 | B7: ='SAME1 Flight Tests 8-27-09'!A45 -> 5 | C7: ='SAME1 Flight Tests 8-27-09'!B45 -> DBP | E7: ='SAME1 Flight Tests 8-27-09'!C45 -> 36 D a | F7: ='SAME1 Flight Tests 8-27-09'!D45 -> 6 | G7: ='SAME1 Flight Tests 8-27-09'!E45 -> 36a | H7: ='SAME1 Flight Tests 8-27-09'!F45 -> Aging | I7: ='SAME1 Flight Tests 8-27-09'!G45 -> 0 | J7: ='SAME1 Flight Tests 8-27-09'!H45 -> 0 | K7: ='SAME1 Flight Tests 8-27-09'!I45 -> 0 | L7: ='SAME1 Flight Tests 8-27-09'!J45 -> n | ... R7: ='SAME1 Flight Tests 8-27-09'!P45 -> 8 | U7: ='SAME1 Flight Tests 8-27-09'!Q45 -> 869 | AA7: ='SAME1 Flight Tests 8-27-09'!R45 -> y | AB7: ='SAME1 Flight Tests 8-27-09'!S45 -> y | AC7: ='SAME1 Flight Tests 8-27-09'!T45 -> 1 | AE7: ='SAME1 Flight Tests 8-27-09'!U45 -> 10 | AG7: ='SAME1 Flight Tests 8-27-09'!V45 -> 0.13253466 | AH7: ='SAME1 Flight Tests 8-27-09'!W45 -> 0.37495252 | AU7: ='SAME1 Flight Tests 8-27-09'!X45 -> n/a | AV7: ='SAME1 Flight Tests 8-27-09'!Y45 -> 3.0097505 | AW7: ='SAME1 Flight Tests 8-27-09'!Z45 -> 6.245758 | AX7: ='SAME1 Flight Tests 8-27-09'!AA45 -> -0.000671386 | BA7: ='SAME1 Flight Tests 8-27-09'!AC45 -> 4.8875265 | BD7: ='SAME1 Flight Tests 8-27-09'!AB45 -> 5.3468635 | BE7: ='SAME1 Flight Tests 8-27-09'!AD45 -> 4.7010045 | BF7: ='SAME1 Flight Tests 8-27-09'!AE45 -> 9022 | BI7: ='SAME1 Flight Tests 8-27-09'!AF45 -> 1.54625 | BJ7: ='SAME1 Flight Tests 8-27-09'!AG45 -> 77.79665 | BK7: ='SAME1 Flight Tests 8-27-09'!AH45 -> 0.645859 | BL7: ='SAME1 Flight Tests 8-27-09'!AK45 -> 0 | BM7: ='SAME1 Flight Tests 8-27-09'!AL45 -> 0 | BQ7: ='SAME1 Flight Tests 8-27-09'!AM45 -> 0 | BR7: ='SAME1 Flight Tests 8-27-09'!AP45 -> 0 | BS7: ='SAME1 Flight Tests 8-27-09'!AQ45 -> 0 | BU7: ='SAME1 Flight Tests 8-27-09'!AS45 -> 0 | BV7: ='SAME1 Flight Tests 8-27-09'!AT45 -> 0 | BW7: ='SAME1 Flight Tests 8-27-09'!BB45 -> 95277.629 | BX7: ='SAME1 Flight Tests 8-27-09'!BC45 -> 93711.955 | BY7: ='SAME1 Flight Tests 8-27-09'!BD45 -> 89033.859 | CA7: ='SAME1 Flight Tests 8-27-09'!BG45 -> 0 | CB7: ='SAME1 Flight Tests 8-27-09'!BF45 -> 0 | CD7: ='SAME1 Flight Tests 8-27-09'!BE45 -> 0
A8: 1 | B8: ='SAME1 Flight Tests 8-27-09'!A46 -> 5 | C8: ='SAME1 Flight Tests 8-27-09'!B46 -> DBP | E8: ='SAME1 Flight Tests 8-27-09'!C46 -> 37 D | F8: ='SAME1 Flight Tests 8-27-09'!D46 -> 6 | G8: ='SAME1 Flight Tests 8-27-09'!E46 -> 37 | H8: ='SAME1 Flight Tests 8-27-09'!F46 -> baseline repeat | I8: ='SAME1 Flight Tests 8-27-09'!G46 -> 276 | J8: ='SAME1 Flight Tests 8-27-09'!H46 -> 39358 | K8: ='SAME1 Flight Tests 8-27-09'!I46 -> 0 | L8: ='SAME1 Flight Tests 8-27-09'!J46 -> n | ... R8: ='SAME1 Flight Tests 8-27-09'!P46 -> 8 | U8: ='SAME1 Flight Tests 8-27-09'!Q46 -> 39 | AA8: ='SAME1 Flight Tests 8-27-09'!R46 -> y | AB8: ='SAME1 Flight Tests 8-27-09'!S46 -> y | AC8: ='SAME1 Flight Tests 8-27-09'!T46 -> 1 | AE8: ='SAME1 Flight Tests 8-27-09'!U46 -> 10 | AG8: ='SAME1 Flight Tests 8-27-09'!V46 -> 0.13253466 | AH8: ='SAME1 Flight Tests 8-27-09'!W46 -> 0 | AU8: ='SAME1 Flight Tests 8-27-09'!X46 -> n/a | AV8: ='SAME1 Flight Tests 8-27-09'!Y46 -> 2.90506 | AW8: ='SAME1 Flight Tests 8-27-09'!Z46 -> 6.246857 | AX8: ='SAME1 Flight Tests 8-27-09'!AA46 -> 5.133179 | BA8: ='SAME1 Flight Tests 8-27-09'!AC46 -> 4.928528 | BD8: ='SAME1 Flight Tests 8-27-09'!AB46 -> 5.3823695 | BE8: ='SAME1 Flight Tests 8-27-09'!AD46 -> 4.699021 | BF8: ='SAME1 Flight Tests 8-27-09'!AE46 -> 5336 | BI8: ='SAME1 Flight Tests 8-27-09'!AF46 -> 0.13735 | BJ8: ='SAME1 Flight Tests 8-27-09'!AG46 -> 95.78285 | BK8: ='SAME1 Flight Tests 8-27-09'!AH46 -> 0.6833485 | BL8: ='SAME1 Flight Tests 8-27-09'!AK46 -> 0 | BM8: ='SAME1 Flight Tests 8-27-09'!AL46 -> 0 | BQ8: ='SAME1 Flight Tests 8-27-09'!AM46 -> 0 | BR8: ='SAME1 Flight Tests 8-27-09'!AP46 -> 0 | BS8: ='SAME1 Flight Tests 8-27-09'!AQ46 -> 0 | BU8: ='SAME1 Flight Tests 8-27-09'!AS46 -> 0 | BV8: ='SAME1 Flight Tests 8-27-09'!AT46 -> 0 | BW8: ='SAME1 Flight Tests 8-27-09'!BB46 -> 56054.495 | BX8: ='SAME1 Flight Tests 8-27-09'!BC46 -> 55128.488 | BY8: ='SAME1 Flight Tests 8-27-09'!BD46 -> 52510.063 | CA8: ='SAME1 Flight Tests 8-27-09'!BG46 -> 0 | CB8: ='SAME1 Flight Tests 8-27-09'!BF46 -> 0 | CD8: ='SAME1 Flight Tests 8-27-09'!BE46 -> 0
A9: 1 | B9: ='SAME1 Flight Tests 8-27-09'!A47 -> 5 | C9: ='SAME1 Flight Tests 8-27-09'!B47 -> DBP | E9: ='SAME1 Flight Tests 8-27-09'!C47 -> 38 D | F9: ='SAME1 Flight Tests 8-27-09'!D47 -> 6 | G9: ='SAME1 Flight Tests 8-27-09'!E47 -> 38 | H9: ='SAME1 Flight Tests 8-27-09'!F47 -> low flow aging | I9: ='SAME1 Flight Tests 8-27-09'!G47 -> 276 | J9: ='SAME1 Flight Tests 8-27-09'!H47 -> 39358 | K9: ='SAME1 Flight Tests 8-27-09'!I47 -> 0 | L9: ='SAME1 Flight Tests 8-27-09'!J47 -> n | ... R9: ='SAME1 Flight Tests 8-27-09'!P47 -> 8 | U9: ='SAME1 Flight Tests 8-27-09'!Q47 -> 49 | AA9: ='SAME1 Flight Tests 8-27-09'!R47 -> y | AB9: ='SAME1 Flight Tests 8-27-09'!S47 -> y | AC9: ='SAME1 Flight Tests 8-27-09'!T47 -> 1 | AE9: ='SAME1 Flight Tests 8-27-09'!U47 -> 10 | AG9: ='SAME1 Flight Tests 8-27-09'!V47 -> 0.13253466 | AH9: ='SAME1 Flight Tests 8-27-09'!W47 -> 0.37128115 | AU9: ='SAME1 Flight Tests 8-27-09'!X47 -> n/a | AV9: ='SAME1 Flight Tests 8-27-09'!Y47 -> 3.1960584 | AW9: ='SAME1 Flight Tests 8-27-09'!Z47 -> 6.2530374 | AX9: ='SAME1 Flight Tests 8-27-09'!AA47 -> -0.00067459884 | BA9: ='SAME1 Flight Tests 8-27-09'!AC47 -> 4.845245 | BD9: ='SAME1 Flight Tests 8-27-09'!AB47 -> 4.9743642 | BE9: ='SAME1 Flight Tests 8-27-09'!AD47 -> 4.663254 | BF9: ='SAME1 Flight Tests 8-27-09'!AE47 -> 1221.1 | BI9: ='SAME1 Flight Tests 8-27-09'!AF47 -> 0.012947368 | BJ9: ='SAME1 Flight Tests 8-27-09'!AG47 -> 42.715737 | BK9: ='SAME1 Flight Tests 8-27-09'!AH47 -> 0.31111021 | BL9: ='SAME1 Flight Tests 8-27-09'!AK47 -> 0 | BM9: ='SAME1 Flight Tests 8-27-09'!AL47 -> 0 | BQ9: ='SAME1 Flight Tests 8-27-09'!AM47 -> 0 | BR9: ='SAME1 Flight Tests 8-27-09'!AP47 -> 0 | BS9: ='SAME1 Flight Tests 8-27-09'!AQ47 -> 0 | BU9: ='SAME1 Flight Tests 8-27-09'!AS47 -> 0 | BV9: ='SAME1 Flight Tests 8-27-09'!AT47 -> 0 | BW9: ='SAME1 Flight Tests 8-27-09'!BB47 -> 12751.788 | BX9: ='SAME1 Flight Tests 8-27-09'!BC47 -> 12539.879 | BY9: ='SAME1 Flight Tests 8-27-09'!BD47 -> 11978.586 | CA9: ='SAME1 Flight Tests 8-27-09'!BG47 -> 0 | CB9: ='SAME1 Flight Tests 8-27-09'!BF47 -> 0 | CD9: ='SAME1 Flight Tests 8-27-09'!BE47 -> 0
A10: 1 | B10: ='SAME1 Flight Tests 8-27-09'!A48 -> 5 | C10: ='SAME1 Flight Tests 8-27-09'!B48 -> DBP | E10: ='SAME1 Flight Tests 8-27-09'!C48 -> 38 D a | F10: ='SAME1 Flight Tests 8-27-09'!D48 -> 6 | G10: ='SAME1 Flight Tests 8-27-09'!E48 -> 38a | H10: ='SAME1 Flight Tests 8-27-09'!F48 -> Aging | I10: ='SAME1 Flight Tests 8-27-09'!G48 -> 276 | J10: ='SAME1 Flight Tests 8-27-09'!H48 -> 39358 | K10: ='SAME1 Flight Tests 8-27-09'!I48 -> 0 | L10: ='SAME1 Flight Tests 8-27-09'!J48 -> n | ... R10: ='SAME1 Flight Tests 8-27-09'!P48 -> 8 | U10: ='SAME1 Flight Tests 8-27-09'!Q48 -> 859 | AA10: ='SAME1 Flight Tests 8-27-09'!R48 -> y | AB10: ='SAME1 Flight Tests 8-27-09'!S48 -> y | AC10: ='SAME1 Flight Tests 8-27-09'!T48 -> 1 | AE10: ='SAME1 Flight Tests 8-27-09'!U48 -> 10 | AG10: ='SAME1 Flight Tests 8-27-09'!V48 -> 0.13253466 | AH10: ='SAME1 Flight Tests 8-27-09'!W48 -> 0.31509757 | AU10: ='SAME1 Flight Tests 8-27-09'!X48 -> n/a | AV10: ='SAME1 Flight Tests 8-27-09'!Y48 -> 3.2435455 | AW10: ='SAME1 Flight Tests 8-27-09'!Z48 -> 6.256577 | AX10: ='SAME1 Flight Tests 8-27-09'!AA48 -> -0.0005798338 | BA10: ='SAME1 Flight Tests 8-27-09'!AC48 -> 4.8681945 | BD10: ='SAME1 Flight Tests 8-27-09'!AB48 -> 4.9144435 | BE10: ='SAME1 Flight Tests 8-27-09'!AD48 -> 4.6818555 | BF10: ='SAME1 Flight Tests 8-27-09'!AE48 -> 973.2 | BI10: ='SAME1 Flight Tests 8-27-09'!AF48 -> 0.01215 | BJ10: ='SAME1 Flight Tests 8-27-09'!AG48 -> 29.3572 | BK10: ='SAME1 Flight Tests 8-27-09'!AH48 -> 0.232588 | BL10: ='SAME1 Flight Tests 8-27-09'!AK48 -> 0 | BM10: ='SAME1 Flight Tests 8-27-09'!AL48 -> 0 | BQ10: ='SAME1 Flight Tests 8-27-09'!AM48 -> 0 | BR10: ='SAME1 Flight Tests 8-27-09'!AP48 -> 0 | BS10: ='SAME1 Flight Tests 8-27-09'!AQ48 -> 0 | BU10: ='SAME1 Flight Tests 8-27-09'!AS48 -> 0 | BV10: ='SAME1 Flight Tests 8-27-09'!AT48 -> 0 | BW10: ='SAME1 Flight Tests 8-27-09'!BB48 -> 10159.36 | BX10: ='SAME1 Flight Tests 8-27-09'!BC48 -> 9990.4716 | BY10: ='SAME1 Flight Tests 8-27-09'!BD48 -> 9544.9492 | CA10: ='SAME1 Flight Tests 8-27-09'!BG48 -> 0 | CB10: ='SAME1 Flight Tests 8-27-09'!BF48 -> 0 | CD10: ='SAME1 Flight Tests 8-27-09'!BE48 -> 0
A11: 1 | B11: ='SAME1 Flight Tests 8-27-09'!A49 -> 5 | C11: ='SAME1 Flight Tests 8-27-09'!B49 -> DBP | E11: ='SAME1 Flight Tests 8-27-09'!C49 -> 39 D | F11: ='SAME1 Flight Tests 8-27-09'!D49 -> 6 | G11: ='SAME1 Flight Tests 8-27-09'!E49 -> 39 | H11: ='SAME1 Flight Tests 8-27-09'!F49 -> baseline repeat | I11: ='SAME1 Flight Tests 8-27-09'!G49 -> 276 | J11: ='SAME1 Flight Tests 8-27-09'!H49 -> 39358 | K11: ='SAME1 Flight Tests 8-27-09'!I49 -> 0 | L11: ='SAME1 Flight Tests 8-27-09'!J49 -> n | ... R11: ='SAME1 Flight Tests 8-27-09'!P49 -> 8 | U11: ='SAME1 Flight Tests 8-27-09'!Q49 -> 58 | AA11: ='SAME1 Flight Tests 8-27-09'!R49 -> y | AB11: ='SAME1 Flight Tests 8-27-09'!S49 -> y | AC11: ='SAME1 Flight Tests 8-27-09'!T49 -> 1 | AE11: ='SAME1 Flight Tests 8-27-09'!U49 -> 10 | AG11: ='SAME1 Flight Tests 8-27-09'!V49 -> 0.13253466 | AH11: ='SAME1 Flight Tests 8-27-09'!W49 -> 0.36986684 | AU11: ='SAME1 Flight Tests 8-27-09'!X49 -> n/a | AV11: ='SAME1 Flight Tests 8-27-09'!Y49 -> 3.028138 | AW11: ='SAME1 Flight Tests 8-27-09'!Z49 -> 6.235765 | AX11: ='SAME1 Flight Tests 8-27-09'!AA49 -> -0.0005645753 | BA11: ='SAME1 Flight Tests 8-27-09'!AC49 -> 4.8626705 | BD11: ='SAME1 Flight Tests 8-27-09'!AB49 -> 5.2797085 | BE11: ='SAME1 Flight Tests 8-27-09'!AD49 -> 4.6674345 | BF11: ='SAME1 Flight Tests 8-27-09'!AE49 -> 4181 | BI11: ='SAME1 Flight Tests 8-27-09'!AF49 -> 0.05735 | BJ11: ='SAME1 Flight Tests 8-27-09'!AG49 -> 73.8926 | BK11: ='SAME1 Flight Tests 8-27-09'!AH49 -> 0.612274 | BL11: ='SAME1 Flight Tests 8-27-09'!AK49 -> 0 | BM11: ='SAME1 Flight Tests 8-27-09'!AL49 -> 0 | BQ11: ='SAME1 Flight Tests 8-27-09'!AM49 -> 0 | BR11: ='SAME1 Flight Tests 8-27-09'!AP49 -> 0 | BS11: ='SAME1 Flight Tests 8-27-09'!AQ49 -> 0 | BU11: ='SAME1 Flight Tests 8-27-09'!AS49 -> 0 | BV11: ='SAME1 Flight Tests 8-27-09'!AT49 -> 0 | BW11: ='SAME1 Flight Tests 8-27-09'!BB49 -> 43848.387 | BX11: ='SAME1 Flight Tests 8-27-09'!BC49 -> 43122.819 | BY11: ='SAME1 Flight Tests 8-27-09'!BD49 -> 41107.599 | CA11: ='SAME1 Flight Tests 8-27-09'!BG49 -> 0 | CB11: ='SAME1 Flight Tests 8-27-09'!BF49 -> 0 | CD11: ='SAME1 Flight Tests 8-27-09'!BE49 -> 0
A12: 1 | B12: ='SAME1 Flight Tests 8-27-09'!A50 -> 5 | C12: ='SAME1 Flight Tests 8-27-09'!B50 -> DBP | E12: ='SAME1 Flight Tests 8-27-09'!C50 -> 39 D a | F12: ='SAME1 Flight Tests 8-27-09'!D50 -> 6 | G12: ='SAME1 Flight Tests 8-27-09'!E50 -> 39a | H12: ='SAME1 Flight Tests 8-27-09'!F50 -> Aging | I12: ='SAME1 Flight Tests 8-27-09'!G50 -> 276 | J12: ='SAME1 Flight Tests 8-27-09'!H50 -> 39358 | K12: ='SAME1 Flight Tests 8-27-09'!I50 -> 0 | L12: ='SAME1 Flight Tests 8-27-09'!J50 -> n | ... R12: ='SAME1 Flight Tests 8-27-09'!P50 -> 8 | U12: ='SAME1 Flight Tests 8-27-09'!Q50 -> 883 | AA12: ='SAME1 Flight Tests 8-27-09'!R50 -> y | AB12: ='SAME1 Flight Tests 8-27-09'!S50 -> y | AC12: ='SAME1 Flight Tests 8-27-09'!T50 -> 1 | AE12: ='SAME1 Flight Tests 8-27-09'!U50 -> 10 | AG12: ='SAME1 Flight Tests 8-27-09'!V50 -> 0.13253466 | AH12: ='SAME1 Flight Tests 8-27-09'!W50 -> 0.33978426 | AU12: ='SAME1 Flight Tests 8-27-09'!X50 -> n/a | AV12: ='SAME1 Flight Tests 8-27-09'!Y50 -> 3.02681 | AW12: ='SAME1 Flight Tests 8-27-09'!Z50 -> 6.2445835 | AX12: ='SAME1 Flight Tests 8-27-09'!AA50 -> -0.00054931635 | BA12: ='SAME1 Flight Tests 8-27-09'!AC50 -> 4.8774255 | BD12: ='SAME1 Flight Tests 8-27-09'!AB50 -> 5.206115 | BE12: ='SAME1 Flight Tests 8-27-09'!AD50 -> 4.6884005 | BF12: ='SAME1 Flight Tests 8-27-09'!AE50 -> 3788 | BI12: ='SAME1 Flight Tests 8-27-09'!AF50 -> 0.06115 | BJ12: ='SAME1 Flight Tests 8-27-09'!AG50 -> 64.9308 | BK12: ='SAME1 Flight Tests 8-27-09'!AH50 -> 0.5177145 | BL12: ='SAME1 Flight Tests 8-27-09'!AK50 -> 0 | BM12: ='SAME1 Flight Tests 8-27-09'!AL50 -> 0 | BQ12: ='SAME1 Flight Tests 8-27-09'!AM50 -> 0 | BR12: ='SAME1 Flight Tests 8-27-09'!AP50 -> 0 | BS12: ='SAME1 Flight Tests 8-27-09'!AQ50 -> 0 | BU12: ='SAME1 Flight Tests 8-27-09'!AS50 -> 0 | BV12: ='SAME1 Flight Tests 8-27-09'!AT50 -> 0 | BW12: ='SAME1 Flight Tests 8-27-09'!BB50 -> 39704.321 | BX12: ='SAME1 Flight Tests 8-27-09'!BC50 -> 39046.953 | BY12: ='SAME1 Flight Tests 8-27-09'!BD50 -> 37232.39 | CA12: ='SAME1 Flight Tests 8-27-09'!BG50 -> 0 | CB12: ='SAME1 Flight Tests 8-27-09'!BF50 -> 0 | CD12: ='SAME1 Flight Tests 8-27-09'!BE50 -> 0
A13: 1 | B13: ='SAME1 Flight Tests 8-27-09'!A51 -> 5 | C13: ='SAME1 Flight Tests 8-27-09'!B51 -> DBP | E13: ='SAME1 Flight Tests 8-27-09'!C51 -> 40 D | F13: ='SAME1 Flight Tests 8-27-09'!D51 -> 6 | G13: ='SAME1 Flight Tests 8-27-09'!E51 -> 40 | H13: ='SAME1 Flight Tests 8-27-09'!F51 -> low flow aging | I13: ='SAME1 Flight Tests 8-27-09'!G51 -> 276 | J13: ='SAME1 Flight Tests 8-27-09'!H51 -> 39358 | K13: ='SAME1 Flight Tests 8-27-09'!I51 -> 0 | L13: ='SAME1 Flight Tests 8-27-09'!J51 -> n | ... R13: ='SAME1 Flight Tests 8-27-09'!P51 -> 8 | U13: ='SAME1 Flight Tests 8-27-09'!Q51 -> 44 | AA13: ='SAME1 Flight Tests 8-27-09'!R51 -> y | AB13: ='SAME1 Flight Tests 8-27-09'!S51 -> y | AC13: ='SAME1 Flight Tests 8-27-09'!T51 -> 1 | AE13: ='SAME1 Flight Tests 8-27-09'!U51 -> 10 | AG13: ='SAME1 Flight Tests 8-27-09'!V51 -> 0.13253466 | AH13: ='SAME1 Flight Tests 8-27-09'!W51 -> 0.37159331 | AU13: ='SAME1 Flight Tests 8-27-09'!X51 -> 13.28 | AV13: ='SAME1 Flight Tests 8-27-09'!Y51 -> 3.272279 | AW13: ='SAME1 Flight Tests 8-27-09'!Z51 -> 6.254395 | AX13: ='SAME1 Flight Tests 8-27-09'!AA51 -> -0.00061035165 | BA13: ='SAME1 Flight Tests 8-27-09'!AC51 -> 4.8564145 | BD13: ='SAME1 Flight Tests 8-27-09'!AB51 -> 4.8485715 | BE13: ='SAME1 Flight Tests 8-27-09'!AD51 -> 4.67064 | BF13: ='SAME1 Flight Tests 8-27-09'!AE51 -> 580.65 | BI13: ='SAME1 Flight Tests 8-27-09'!AF51 -> 0.01575 | BJ13: ='SAME1 Flight Tests 8-27-09'!AG51 -> 25.5459 | BK13: ='SAME1 Flight Tests 8-27-09'!AH51 -> 0.1779315 | BL13: ='SAME1 Flight Tests 8-27-09'!AK51 -> 0 | BM13: ='SAME1 Flight Tests 8-27-09'!AL51 -> 0 | BQ13: ='SAME1 Flight Tests 8-27-09'!AM51 -> 0 | BR13: ='SAME1 Flight Tests 8-27-09'!AP51 -> 0 | BS13: ='SAME1 Flight Tests 8-27-09'!AQ51 -> 0 | BU13: ='SAME1 Flight Tests 8-27-09'!AS51 -> 0 | BV13: ='SAME1 Flight Tests 8-27-09'!AT51 -> 0 | BW13: ='SAME1 Flight Tests 8-27-09'!BB51 -> 6058.0406 | BX13: ='SAME1 Flight Tests 8-27-09'!BC51 -> 5957.2749 | BY13: ='SAME1 Flight Tests 8-27-09'!BD51 -> 5693.1782 | CA13: ='SAME1 Flight Tests 8-27-09'!BG51 -> 0 | CB13: ='SAME1 Flight Tests 8-27-09'!BF51 -> 0 | CD13: ='SAME1 Flight Tests 8-27-09'!BE51 -> 0
A14: 1 | B14: ='SAME1 Flight Tests 8-27-09'!A52 -> 5 | C14: ='SAME1 Flight Tests 8-27-09'!B52 -> DBP | E14: ='SAME1 Flight Tests 8-27-09'!C52 -> 40 D a | F14: ='SAME1 Flight Tests 8-27-09'!D52 -> 6 | G14: ='SAME1 Flight Tests 8-27-09'!E52 -> 40a | H14: ='SAME1 Flight Tests 8-27-09'!F52 -> Aging | I14: ='SAME1 Flight Tests 8-27-09'!G52 -> 276 | J14: ='SAME1 Flight Tests 8-27-09'!H52 -> 39358 | K14: ='SAME1 Flight Tests 8-27-09'!I52 -> 0 | L14: ='SAME1 Flight Tests 8-27-09'!J52 -> n | ... R14: ='SAME1 Flight Tests 8-27-09'!P52 -> 8 | U14: ='SAME1 Flight Tests 8-27-09'!Q52 -> 860 | AA14: ='SAME1 Flight Tests 8-27-09'!R52 -> y | AB14: ='SAME1 Flight Tests 8-27-09'!S52 -> y | AC14: ='SAME1 Flight Tests 8-27-09'!T52 -> 1 | AE14: ='SAME1 Flight Tests 8-27-09'!U52 -> 10 | AG14: ='SAME1 Flight Tests 8-27-09'!V52 -> 0.13253466 | AH14: ='SAME1 Flight Tests 8-27-09'!W52 -> 0.28657151 | AU14: ='SAME1 Flight Tests 8-27-09'!X52 -> 13.28 | AV14: ='SAME1 Flight Tests 8-27-09'!Y52 -> 3.320434 | AW14: ='SAME1 Flight Tests 8-27-09'!Z52 -> 6.20639 | AX14: ='SAME1 Flight Tests 8-27-09'!AA52 -> -0.0007934564 | BA14: ='SAME1 Flight Tests 8-27-09'!AC52 -> 4.8695365 | BD14: ='SAME1 Flight Tests 8-27-09'!AB52 -> 4.7945105 | BE14: ='SAME1 Flight Tests 8-27-09'!AD52 -> 4.677658 | BF14: ='SAME1 Flight Tests 8-27-09'!AE52 -> 473.25 | BI14: ='SAME1 Flight Tests 8-27-09'!AF52 -> 0.01725 | BJ14: ='SAME1 Flight Tests 8-27-09'!AG52 -> 17.5287 | BK14: ='SAME1 Flight Tests 8-27-09'!AH52 -> 0.1168525 | BL14: ='SAME1 Flight Tests 8-27-09'!AK52 -> 0 | BM14: ='SAME1 Flight Tests 8-27-09'!AL52 -> 0 | BQ14: ='SAME1 Flight Tests 8-27-09'!AM52 -> 0 | BR14: ='SAME1 Flight Tests 8-27-09'!AP52 -> 0 | BS14: ='SAME1 Flight Tests 8-27-09'!AQ52 -> 0 | BU14: ='SAME1 Flight Tests 8-27-09'!AS52 -> 0 | BV14: ='SAME1 Flight Tests 8-27-09'!AT52 -> 0 | BW14: ='SAME1 Flight Tests 8-27-09'!BB52 -> 4936.7473 | BX14: ='SAME1 Flight Tests 8-27-09'!BC52 -> 4854.6198 | BY14: ='SAME1 Flight Tests 8-27-09'!BD52 -> 4639.7553 | CA14: ='SAME1 Flight Tests 8-27-09'!BG52 -> 0 | CB14: ='SAME1 Flight Tests 8-27-09'!BF52 -> 0 | CD14: ='SAME1 Flight Tests 8-27-09'!BE52 -> 0
A15: 1 | B15: ='SAME1 Flight Tests 8-27-09'!A55 -> 5 | C15: ='SAME1 Flight Tests 8-27-09'!B55 -> DBP | E15: ='SAME1 Flight Tests 8-27-09'!C55 -> 42 D | F15: ='SAME1 Flight Tests 8-27-09'!D55 -> 5 | G15: ='SAME1 Flight Tests 8-27-09'!E55 -> 42 | H15: ='SAME1 Flight Tests 8-27-09'!F55 -> low flow aging | I15: ='SAME1 Flight Tests 8-27-09'!G55 -> 277 | J15: ='SAME1 Flight Tests 8-27-09'!H55 -> 39359 | K15: ='SAME1 Flight Tests 8-27-09'!I55 -> 0 | L15: ='SAME1 Flight Tests 8-27-09'!J55 -> n | ... R15: ='SAME1 Flight Tests 8-27-09'!P55 -> 8 | U15: ='SAME1 Flight Tests 8-27-09'!Q55 -> 65 | AA15: ='SAME1 Flight Tests 8-27-09'!R55 -> y | AB15: ='SAME1 Flight Tests 8-27-09'!S55 -> y | AC15: ='SAME1 Flight Tests 8-27-09'!T55 -> 1 | AE15: ='SAME1 Flight Tests 8-27-09'!U55 -> 10 | AG15: ='SAME1 Flight Tests 8-27-09'!V55 -> 0.13253466 | AH15: ='SAME1 Flight Tests 8-27-09'!W55 -> 0.37038216 | AU15: ='SAME1 Flight Tests 8-27-09'!X55 -> n/a | AV15: ='SAME1 Flight Tests 8-27-09'!Y55 -> 3.15973 | AW15: ='SAME1 Flight Tests 8-27-09'!Z55 -> 6.240723 | AX15: ='SAME1 Flight Tests 8-27-09'!AA55 -> -0.0008239742 | BA15: ='SAME1 Flight Tests 8-27-09'!AC55 -> 4.8665015 | BD15: ='SAME1 Flight Tests 8-27-09'!AB55 -> 5.2604235 | BE15: ='SAME1 Flight Tests 8-27-09'!AD55 -> 4.689452 | BF15: ='SAME1 Flight Tests 8-27-09'!AE55 -> 6631.5 | BI15: ='SAME1 Flight Tests 8-27-09'!AF55 -> 1.5378 | BJ15: ='SAME1 Flight Tests 8-27-09'!AG55 -> 56.6251 | BK15: ='SAME1 Flight Tests 8-27-09'!AH55 -> 0.5709715 | BL15: ='SAME1 Flight Tests 8-27-09'!AK55 -> 0 | BM15: ='SAME1 Flight Tests 8-27-09'!AL55 -> 0 | BQ15: ='SAME1 Flight Tests 8-27-09'!AM55 -> 0 | BR15: ='SAME1 Flight Tests 8-27-09'!AP55 -> 0 | BS15: ='SAME1 Flight Tests 8-27-09'!AQ55 -> 0 | BU15: ='SAME1 Flight Tests 8-27-09'!AS55 -> 0 | BV15: ='SAME1 Flight Tests 8-27-09'!AT55 -> 0 | BW15: ='SAME1 Flight Tests 8-27-09'!BB55 -> 69793.32 | BX15: ='SAME1 Flight Tests 8-27-09'!BC55 -> 68642.493 | BY15: ='SAME1 Flight Tests 8-27-09'!BD55 -> 65323.532 | CA15: ='SAME1 Flight Tests 8-27-09'!BG55 -> 0 | CB15: ='SAME1 Flight Tests 8-27-09'!BF55 -> 0 | CD15: ='SAME1 Flight Tests 8-27-09'!BE55 -> 0
A16: 1 | B16: ='SAME1 Flight Tests 8-27-09'!A56 -> 5 | C16: ='SAME1 Flight Tests 8-27-09'!B56 -> DBP | E16: ='SAME1 Flight Tests 8-27-09'!C56 -> 42 D a | F16: ='SAME1 Flight Tests 8-27-09'!D56 -> 5 | G16: ='SAME1 Flight Tests 8-27-09'!E56 -> 42a | H16: ='SAME1 Flight Tests 8-27-09'!F56 -> Aging | I16: ='SAME1 Flight Tests 8-27-09'!G56 -> 277 | J16: ='SAME1 Flight Tests 8-27-09'!H56 -> 39359 | K16: ='SAME1 Flight Tests 8-27-09'!I56 -> 0 | L16: ='SAME1 Flight Tests 8-27-09'!J56 -> n | ... R16: ='SAME1 Flight Tests 8-27-09'!P56 -> 8 | U16: ='SAME1 Flight Tests 8-27-09'!Q56 -> 871 | AA16: ='SAME1 Flight Tests 8-27-09'!R56 -> y | AB16: ='SAME1 Flight Tests 8-27-09'!S56 -> y | AC16: ='SAME1 Flight Tests 8-27-09'!T56 -> 1 | AE16: ='SAME1 Flight Tests 8-27-09'!U56 -> 10 | AG16: ='SAME1 Flight Tests 8-27-09'!V56 -> 0.13253466 | AH16: ='SAME1 Flight Tests 8-27-09'!W56 -> 0.37487608 | AU16: ='SAME1 Flight Tests 8-27-09'!X56 -> n/a | AV16: ='SAME1 Flight Tests 8-27-09'!Y56 -> 3.173995 | AW16: ='SAME1 Flight Tests 8-27-09'!Z56 -> 6.2468415 | AX16: ='SAME1 Flight Tests 8-27-09'!AA56 -> -0.0007476806 | BA16: ='SAME1 Flight Tests 8-27-09'!AC56 -> 4.8921345 | BD16: ='SAME1 Flight Tests 8-27-09'!AB56 -> 5.176146 | BE16: ='SAME1 Flight Tests 8-27-09'!AD56 -> 4.6991875 | BF16: ='SAME1 Flight Tests 8-27-09'!AE56 -> 5762 | BI16: ='SAME1 Flight Tests 8-27-09'!AF56 -> 1.2408 | BJ16: ='SAME1 Flight Tests 8-27-09'!AG56 -> 50.4482 | BK16: ='SAME1 Flight Tests 8-27-09'!AH56 -> 0.4769585 | BL16: ='SAME1 Flight Tests 8-27-09'!AK56 -> 0 | BM16: ='SAME1 Flight Tests 8-27-09'!AL56 -> 0 | BQ16: ='SAME1 Flight Tests 8-27-09'!AM56 -> 0 | BR16: ='SAME1 Flight Tests 8-27-09'!AP56 -> 0 | BS16: ='SAME1 Flight Tests 8-27-09'!AQ56 -> 0 | BU16: ='SAME1 Flight Tests 8-27-09'!AS56 -> 0 | BV16: ='SAME1 Flight Tests 8-27-09'!AT56 -> 0 | BW16: ='SAME1 Flight Tests 8-27-09'!BB56 -> 60566.651 | BX16: ='SAME1 Flight Tests 8-27-09'!BC56 -> 59566.716 | BY16: ='SAME1 Flight Tests 8-27-09'!BD56 -> 56720.728 | CA16: ='SAME1 Flight Tests 8-27-09'!BG56 -> 0 | CB16: ='SAME1 Flight Tests 8-27-09'!BF56 -> 0 | CD16: ='SAME1 Flight Tests 8-27-09'!BE56 -> 0
A17: 1 | B17: ='SAME1 Flight Tests 8-27-09'!A57 -> 5 | C17: ='SAME1 Flight Tests 8-27-09'!B57 -> DBP | E17: ='SAME1 Flight Tests 8-27-09'!C57 -> 43 D | F17: ='SAME1 Flight Tests 8-27-09'!D57 -> 5 | G17: ='SAME1 Flight Tests 8-27-09'!E57 -> 43 | H17: ='SAME1 Flight Tests 8-27-09'!F57 -> low tempng | I17: ='SAME1 Flight Tests 8-27-09'!G57 -> 277 | J17: ='SAME1 Flight Tests 8-27-09'!H57 -> 39359 | K17: ='SAME1 Flight Tests 8-27-09'!I57 -> 0 | L17: ='SAME1 Flight Tests 8-27-09'!J57 -> n | ... R17: ='SAME1 Flight Tests 8-27-09'!P57 -> 8 | U17: ='SAME1 Flight Tests 8-27-09'!Q57 -> 60 | AA17: ='SAME1 Flight Tests 8-27-09'!R57 -> y | AB17: ='SAME1 Flight Tests 8-27-09'!S57 -> y | AC17: ='SAME1 Flight Tests 8-27-09'!T57 -> 1 | AE17: ='SAME1 Flight Tests 8-27-09'!U57 -> 10 | AG17: ='SAME1 Flight Tests 8-27-09'!V57 -> 0.13253466 | AH17: ='SAME1 Flight Tests 8-27-09'!W57 -> 0.371665 | AU17: ='SAME1 Flight Tests 8-27-09'!X57 -> n/a | AV17: ='SAME1 Flight Tests 8-27-09'!Y57 -> 2.9458625 | AW17: ='SAME1 Flight Tests 8-27-09'!Z57 -> 6.25795 | AX17: ='SAME1 Flight Tests 8-27-09'!AA57 -> -0.0004882815 | BA17: ='SAME1 Flight Tests 8-27-09'!AC57 -> 4.838136 | BD17: ='SAME1 Flight Tests 8-27-09'!AB57 -> 5.4415285 | BE17: ='SAME1 Flight Tests 8-27-09'!AD57 -> 4.660476 | BF17: ='SAME1 Flight Tests 8-27-09'!AE57 -> 7059 | BI17: ='SAME1 Flight Tests 8-27-09'!AF57 -> 1.02735 | BJ17: ='SAME1 Flight Tests 8-27-09'!AG57 -> 91.5885 | BK17: ='SAME1 Flight Tests 8-27-09'!AH57 -> 0.7810525 | BL17: ='SAME1 Flight Tests 8-27-09'!AK57 -> 0 | BM17: ='SAME1 Flight Tests 8-27-09'!AL57 -> 0 | BQ17: ='SAME1 Flight Tests 8-27-09'!AM57 -> 0 | BR17: ='SAME1 Flight Tests 8-27-09'!AP57 -> 0 | BS17: ='SAME1 Flight Tests 8-27-09'!AQ57 -> 0 | BU17: ='SAME1 Flight Tests 8-27-09'!AS57 -> 0 | BV17: ='SAME1 Flight Tests 8-27-09'!AT57 -> 0 | BW17: ='SAME1 Flight Tests 8-27-09'!BB57 -> 74338.089 | BX17: ='SAME1 Flight Tests 8-27-09'!BC57 -> 73113.074 | BY17: ='SAME1 Flight Tests 8-27-09'!BD57 -> 69557.386 | CA17: ='SAME1 Flight Tests 8-27-09'!BG57 -> 0 | CB17: ='SAME1 Flight Tests 8-27-09'!BF57 -> 0 | CD17: ='SAME1 Flight Tests 8-27-09'!BE57 -> 0
A18: 1 | B18: ='SAME1 Flight Tests 8-27-09'!A58 -> 5 | C18: ='SAME1 Flight Tests 8-27-09'!B58 -> DBP | E18: ='SAME1 Flight Tests 8-27-09'!C58 -> 43 D a | F18: ='SAME1 Flight Tests 8-27-09'!D58 -> 5 | G18: ='SAME1 Flight Tests 8-27-09'!E58 -> 43a | H18: ='SAME1 Flight Tests 8-27-09'!F58 -> Aging | I18: ='SAME1 Flight Tests 8-27-09'!G58 -> 277 | J18: ='SAME1 Flight Tests 8-27-09'!H58 -> 39359 | K18: ='SAME1 Flight Tests 8-27-09'!I58 -> 0 | L18: ='SAME1 Flight Tests 8-27-09'!J58 -> n | ... R18: ='SAME1 Flight Tests 8-27-09'!P58 -> 8 | U18: ='SAME1 Flight Tests 8-27-09'!Q58 -> 879 | AA18: ='SAME1 Flight Tests 8-27-09'!R58 -> y | AB18: ='SAME1 Flight Tests 8-27-09'!S58 -> y | AC18: ='SAME1 Flight Tests 8-27-09'!T58 -> 1 | AE18: ='SAME1 Flight Tests 8-27-09'!U58 -> 10 | AG18: ='SAME1 Flight Tests 8-27-09'!V58 -> 0.13253466 | AH18: ='SAME1 Flight Tests 8-27-09'!W58 -> 0 | AU18: ='SAME1 Flight Tests 8-27-09'!X58 -> n/a | AV18: ='SAME1 Flight Tests 8-27-09'!Y58 -> 2.960677 | AW18: ='SAME1 Flight Tests 8-27-09'!Z58 -> 6.257324 | AX18: ='SAME1 Flight Tests 8-27-09'!AA58 -> -0.00077819745 | BA18: ='SAME1 Flight Tests 8-27-09'!AC58 -> 4.895783 | BD18: ='SAME1 Flight Tests 8-27-09'!AB58 -> 5.340621 | BE18: ='SAME1 Flight Tests 8-27-09'!AD58 -> 4.6857305 | BF18: ='SAME1 Flight Tests 8-27-09'!AE58 -> 6318 | BI18: ='SAME1 Flight Tests 8-27-09'!AF58 -> 0.84245 | BJ18: ='SAME1 Flight Tests 8-27-09'!AG58 -> 80.2976 | BK18: ='SAME1 Flight Tests 8-27-09'!AH58 -> 0.6548905 | BL18: ='SAME1 Flight Tests 8-27-09'!AK58 -> 0 | BM18: ='SAME1 Flight Tests 8-27-09'!AL58 -> 0 | BQ18: ='SAME1 Flight Tests 8-27-09'!AM58 -> 0 | BR18: ='SAME1 Flight Tests 8-27-09'!AP58 -> 0 | BS18: ='SAME1 Flight Tests 8-27-09'!AQ58 -> 0 | BU18: ='SAME1 Flight Tests 8-27-09'!AS58 -> 0 | BV18: ='SAME1 Flight Tests 8-27-09'!AT58 -> 0 | BW18: ='SAME1 Flight Tests 8-27-09'!BB58 -> 66463.995 | BX18: ='SAME1 Flight Tests 8-27-09'!BC58 -> 65367.573 | BY18: ='SAME1 Flight Tests 8-27-09'!BD58 -> 62220.458 | CA18: ='SAME1 Flight Tests 8-27-09'!BG58 -> 0 | CB18: ='SAME1 Flight Tests 8-27-09'!BF58 -> 0 | CD18: ='SAME1 Flight Tests 8-27-09'!BE58 -> 0
A19: 1 | B19: ='SAME1 Flight Tests 8-27-09'!A59 -> 5 | C19: ='SAME1 Flight Tests 8-27-09'!B59 -> DBP | E19: ='SAME1 Flight Tests 8-27-09'!C59 -> 44 D | F19: ='SAME1 Flight Tests 8-27-09'!D59 -> 5 | G19: ='SAME1 Flight Tests 8-27-09'!E59 -> 44 | H19: ='SAME1 Flight Tests 8-27-09'!F59 -> low temp aging | I19: ='SAME1 Flight Tests 8-27-09'!G59 -> 277 | J19: ='SAME1 Flight Tests 8-27-09'!H59 -> 39359 | K19: ='SAME1 Flight Tests 8-27-09'!I59 -> 0 | L19: ='SAME1 Flight Tests 8-27-09'!J59 -> n | ... R19: ='SAME1 Flight Tests 8-27-09'!P59 -> 8 | U19: ='SAME1 Flight Tests 8-27-09'!Q59 -> 62 | AA19: ='SAME1 Flight Tests 8-27-09'!R59 -> y | AB19: ='SAME1 Flight Tests 8-27-09'!S59 -> y | AC19: ='SAME1 Flight Tests 8-27-09'!T59 -> 1 | AE19: ='SAME1 Flight Tests 8-27-09'!U59 -> 10 | AG19: ='SAME1 Flight Tests 8-27-09'!V59 -> 0.13253466 | AH19: ='SAME1 Flight Tests 8-27-09'!W59 -> 0 | AU19: ='SAME1 Flight Tests 8-27-09'!X59 -> n/a | AV19: ='SAME1 Flight Tests 8-27-09'!Y59 -> 3.186265 | AW19: ='SAME1 Flight Tests 8-27-09'!Z59 -> 6.2593695 | AX19: ='SAME1 Flight Tests 8-27-09'!AA59 -> -0.0005645751 | BA19: ='SAME1 Flight Tests 8-27-09'!AC59 -> 4.8722225 | BD19: ='SAME1 Flight Tests 8-27-09'!AB59 -> 5.119582 | BE19: ='SAME1 Flight Tests 8-27-09'!AD59 -> 4.6912835 | BF19: ='SAME1 Flight Tests 8-27-09'!AE59 -> 2670 | BI19: ='SAME1 Flight Tests 8-27-09'!AF59 -> 0.00265 | BJ19: ='SAME1 Flight Tests 8-27-09'!AG59 -> 47.52135 | BK19: ='SAME1 Flight Tests 8-27-09'!AH59 -> 0.4282985 | BL19: ='SAME1 Flight Tests 8-27-09'!AK59 -> 0 | BM19: ='SAME1 Flight Tests 8-27-09'!AL59 -> 0 | BQ19: ='SAME1 Flight Tests 8-27-09'!AM59 -> 0 | BR19: ='SAME1 Flight Tests 8-27-09'!AP59 -> 0 | BS19: ='SAME1 Flight Tests 8-27-09'!AQ59 -> 0 | BU19: ='SAME1 Flight Tests 8-27-09'!AS59 -> 0 | BV19: ='SAME1 Flight Tests 8-27-09'!AT59 -> 0 | BW19: ='SAME1 Flight Tests 8-27-09'!BB59 -> 27940.84 | BX19: ='SAME1 Flight Tests 8-27-09'!BC59 -> 27477.49 | BY19: ='SAME1 Flight Tests 8-27-09'!BD59 -> 26221.004 | CA19: ='SAME1 Flight Tests 8-27-09'!BG59 -> 0 | CB19: ='SAME1 Flight Tests 8-27-09'!BF59 -> 0 | CD19: ='SAME1 Flight Tests 8-27-09'!BE59 -> 0
A20: 1 | B20: ='SAME1 Flight Tests 8-27-09'!A60 -> 5 | C20: ='SAME1 Flight Tests 8-27-09'!B60 -> DBP | E20: ='SAME1 Flight Tests 8-27-09'!C60 -> 44 D1 | F20: ='SAME1 Flight Tests 8-27-09'!D60 -> 5 | G20: ='SAME1 Flight Tests 8-27-09'!E60 -> 44a | H20: ='SAME1 Flight Tests 8-27-09'!F60 -> Aging | I20: ='SAME1 Flight Tests 8-27-09'!G60 -> 277 | J20: ='SAME1 Flight Tests 8-27-09'!H60 -> 39359 | K20: ='SAME1 Flight Tests 8-27-09'!I60 -> 0 | L20: ='SAME1 Flight Tests 8-27-09'!J60 -> n | ... R20: ='SAME1 Flight Tests 8-27-09'!P60 -> 8 | U20: ='SAME1 Flight Tests 8-27-09'!Q60 -> 1958 | AA20: ='SAME1 Flight Tests 8-27-09'!R60 -> y | AB20: ='SAME1 Flight Tests 8-27-09'!S60 -> y | AC20: ='SAME1 Flight Tests 8-27-09'!T60 -> 1 | AE20: ='SAME1 Flight Tests 8-27-09'!U60 -> 10 | AG20: ='SAME1 Flight Tests 8-27-09'!V60 -> 0.13253466 | AH20: ='SAME1 Flight Tests 8-27-09'!W60 -> 0.37602999 | AU20: ='SAME1 Flight Tests 8-27-09'!X60 -> n/a | AV20: ='SAME1 Flight Tests 8-27-09'!Y60 -> 3.212738 | AW20: ='SAME1 Flight Tests 8-27-09'!Z60 -> 6.2593225 | AX20: ='SAME1 Flight Tests 8-27-09'!AA60 -> -0.00067138675 | BA20: ='SAME1 Flight Tests 8-27-09'!AC60 -> 4.8959057 | BD20: ='SAME1 Flight Tests 8-27-09'!AB60 -> 5.060608 | BE20: ='SAME1 Flight Tests 8-27-09'!AD60 -> 4.7004781 | BF20: ='SAME1 Flight Tests 8-27-09'!AE60 -> 2452 | BI20: ='SAME1 Flight Tests 8-27-09'!AF60 -> 0.00635 | BJ20: ='SAME1 Flight Tests 8-27-09'!AG60 -> 42.2711 | BK20: ='SAME1 Flight Tests 8-27-09'!AH60 -> 0.3601299 | BL20: ='SAME1 Flight Tests 8-27-09'!AK60 -> 0 | BM20: ='SAME1 Flight Tests 8-27-09'!AL60 -> 0 | BQ20: ='SAME1 Flight Tests 8-27-09'!AM60 -> 0 | BR20: ='SAME1 Flight Tests 8-27-09'!AP60 -> 0 | BS20: ='SAME1 Flight Tests 8-27-09'!AQ60 -> 0 | BU20: ='SAME1 Flight Tests 8-27-09'!AS60 -> 0 | BV20: ='SAME1 Flight Tests 8-27-09'!AT60 -> 0 | BW20: ='SAME1 Flight Tests 8-27-09'!BB60 -> 25651.462 | BX20: ='SAME1 Flight Tests 8-27-09'!BC60 -> 25225.943 | BY20: ='SAME1 Flight Tests 8-27-09'!BD60 -> 24076.08 | CA20: ='SAME1 Flight Tests 8-27-09'!BG60 -> 0 | CB20: ='SAME1 Flight Tests 8-27-09'!BF60 -> 0 | CD20: ='SAME1 Flight Tests 8-27-09'!BE60 -> 0
A21: 1 | B21: ='SAME1 Flight Tests 8-27-09'!A61 -> 5 | C21: ='SAME1 Flight Tests 8-27-09'!B61 -> DBP | E21: ='SAME1 Flight Tests 8-27-09'!C61 -> 45 D | F21: ='SAME1 Flight Tests 8-27-09'!D61 -> 5 | G21: ='SAME1 Flight Tests 8-27-09'!E61 -> 45 | H21: ='SAME1 Flight Tests 8-27-09'!F61 -> high temp aging | I21: ='SAME1 Flight Tests 8-27-09'!G61 -> 278 | J21: ='SAME1 Flight Tests 8-27-09'!H61 -> 39360 | K21: ='SAME1 Flight Tests 8-27-09'!I61 -> 0 | L21: ='SAME1 Flight Tests 8-27-09'!J61 -> n | ... R21: ='SAME1 Flight Tests 8-27-09'!P61 -> 8 | U21: ='SAME1 Flight Tests 8-27-09'!Q61 -> 86 | AA21: ='SAME1 Flight Tests 8-27-09'!R61 -> y | AB21: ='SAME1 Flight Tests 8-27-09'!S61 -> y | AC21: ='SAME1 Flight Tests 8-27-09'!T61 -> 1 | AE21: ='SAME1 Flight Tests 8-27-09'!U61 -> 10 | AG21: ='SAME1 Flight Tests 8-27-09'!V61 -> 0.13253466 | AH21: ='SAME1 Flight Tests 8-27-09'!W61 -> 0.37232467 | AU21: ='SAME1 Flight Tests 8-27-09'!X61 -> 8.54 | AV21: ='SAME1 Flight Tests 8-27-09'!Y61 -> 2.992845 | AW21: ='SAME1 Flight Tests 8-27-09'!Z61 -> 6.246277 | AX21: ='SAME1 Flight Tests 8-27-09'!AA61 -> -0.000640869 | BA21: ='SAME1 Flight Tests 8-27-09'!AC61 -> 4.8697975 | BD21: ='SAME1 Flight Tests 8-27-09'!AB61 -> 5.405456 | BE21: ='SAME1 Flight Tests 8-27-09'!AD61 -> 4.7024245 | BF21: ='SAME1 Flight Tests 8-27-09'!AE61 -> 6791 | BI21: ='SAME1 Flight Tests 8-27-09'!AF61 -> 1.2176 | BJ21: ='SAME1 Flight Tests 8-27-09'!AG61 -> 77.6235 | BK21: ='SAME1 Flight Tests 8-27-09'!AH61 -> 0.7030315 | BL21: ='SAME1 Flight Tests 8-27-09'!AK61 -> 0 | BM21: ='SAME1 Flight Tests 8-27-09'!AL61 -> 0 | BQ21: ='SAME1 Flight Tests 8-27-09'!AM61 -> 0 | BR21: ='SAME1 Flight Tests 8-27-09'!AP61 -> 0 | BS21: ='SAME1 Flight Tests 8-27-09'!AQ61 -> 0 | BU21: ='SAME1 Flight Tests 8-27-09'!AS61 -> 0 | BV21: ='SAME1 Flight Tests 8-27-09'!AT61 -> 0 | BW21: ='SAME1 Flight Tests 8-27-09'!BB61 -> 71488.326 | BX21: ='SAME1 Flight Tests 8-27-09'!BC61 -> 70309.819 | BY21: ='SAME1 Flight Tests 8-27-09'!BD61 -> 66902.858 | CA21: ='SAME1 Flight Tests 8-27-09'!BG61 -> 0 | CB21: ='SAME1 Flight Tests 8-27-09'!BF61 -> 0 | CD21: ='SAME1 Flight Tests 8-27-09'!BE61 -> 0
A22: 1 | B22: ='SAME1 Flight Tests 8-27-09'!A62 -> 5 | C22: ='SAME1 Flight Tests 8-27-09'!B62 -> DBP | E22: ='SAME1 Flight Tests 8-27-09'!C62 -> 45 D a | F22: ='SAME1 Flight Tests 8-27-09'!D62 -> 5 | G22: ='SAME1 Flight Tests 8-27-09'!E62 -> 45a | H22: ='SAME1 Flight Tests 8-27-09'!F62 -> Aging | I22: ='SAME1 Flight Tests 8-27-09'!G62 -> 278 | J22: ='SAME1 Flight Tests 8-27-09'!H62 -> 39360 | K22: ='SAME1 Flight Tests 8-27-09'!I62 -> 0 | L22: ='SAME1 Flight Tests 8-27-09'!J62 -> n | ... R22: ='SAME1 Flight Tests 8-27-09'!P62 -> 8 | U22: ='SAME1 Flight Tests 8-27-09'!Q62 -> 554.16667 | AA22: ='SAME1 Flight Tests 8-27-09'!R62 -> y | AB22: ='SAME1 Flight Tests 8-27-09'!S62 -> y | AC22: ='SAME1 Flight Tests 8-27-09'!T62 -> 1 | AE22: ='SAME1 Flight Tests 8-27-09'!U62 -> 10 | AG22: ='SAME1 Flight Tests 8-27-09'!V62 -> 0.13253466 | AH22: ='SAME1 Flight Tests 8-27-09'!W62 -> 0.37661071 | AU22: ='SAME1 Flight Tests 8-27-09'!X62 -> 8.54 | AV22: ='SAME1 Flight Tests 8-27-09'!Y62 -> 3.2190433 | AW22: ='SAME1 Flight Tests 8-27-09'!Z62 -> 4.8937483 | AX22: ='SAME1 Flight Tests 8-27-09'!AA62 -> -0.00076293933 | BA22: ='SAME1 Flight Tests 8-27-09'!AC62 -> 4.90158 | BD22: ='SAME1 Flight Tests 8-27-09'!AB62 -> 5.0084433 | BE22: ='SAME1 Flight Tests 8-27-09'!AD62 -> 4.7215783 | BF22: ='SAME1 Flight Tests 8-27-09'!AE62 -> 3538 | BI22: ='SAME1 Flight Tests 8-27-09'!AF62 -> 0.73383333 | BJ22: ='SAME1 Flight Tests 8-27-09'!AG62 -> 44.691 | BK22: ='SAME1 Flight Tests 8-27-09'!AH62 -> 0.286865 | BL22: ='SAME1 Flight Tests 8-27-09'!AK62 -> 0 | BM22: ='SAME1 Flight Tests 8-27-09'!AL62 -> 0 | BQ22: ='SAME1 Flight Tests 8-27-09'!AM62 -> 0 | BR22: ='SAME1 Flight Tests 8-27-09'!AP62 -> 0 | BS22: ='SAME1 Flight Tests 8-27-09'!AQ62 -> 0 | BU22: ='SAME1 Flight Tests 8-27-09'!AS62 -> 0 | BV22: ='SAME1 Flight Tests 8-27-09'!AT62 -> 0 | BW22: ='SAME1 Flight Tests 8-27-09'!BB62 -> 37070.572 | BX22: ='SAME1 Flight Tests 8-27-09'!BC62 -> 36456.589 | BY22: ='SAME1 Flight Tests 8-27-09'!BD62 -> 34768.457 | CA22: ='SAME1 Flight Tests 8-27-09'!BG62 -> 0 | CB22: ='SAME1 Flight Tests 8-27-09'!BF62 -> 0 | CD22: ='SAME1 Flight Tests 8-27-09'!BE62 -> 0
I23: Print Boundary Print inside the blue border

Sheet Pyrell R&T plots
B1: SAME Combined Results | N1: Smoke Generation | V1: Primary Diagnostics | AI1: Secondary Diagnostics Volume
A2: Flight 1=same 2=sameR, g=ground | B2: Carousel | C2: Sample Type | D2: Sample ID | E2: Test ID Number | F2: Position in Carousel | G2: SAME # | H2: Description | I2: GMT | J2: Date (EST) | K2: TEAM Test ID Number | L2: Fan problem | M2: Flat profiles | N2: Inlet Velocity (cm/sec) | O2: Rt/R0 | P2: Duration (sec) | Q2: Primary Aging Duration (sec) | R2: Primary Mixing Duration (sec) | S2: PreAge Thermal Precipitator | T2: PreAge Thermal Precipitator Duration | U2: Net Aging Duration | V2: Primary Aging Therm Precip | W2: Primary Aging Therm Precip Duration | X2: Use STS Detector | Y2: Use Comm Diag A | Z2: Use Comm Diag B | AA2: Diluting A | AB2: Diluting B | AC2: Impactor Inlet on CDA | AD2: Cyclone Inlet on CDA (MPASS) | AE2: Impactor Inlet on CDB | AF2: Use P-Trak | AG2: Aerosol Concentration To P-Trak | AH2: Aerosol Conteration to DustTrak | AI2: Secondary Diagnostics Volume % | AJ2: Secondary Aging Duration (sec) | AK2: Secondary Mixing Duration (sec) | AL2: STSDetector | AM2: Comm Diag A | AN2: Comm Diag B | AO2: Diluting A | AP2: Diluting B | AQ2: Ues PTrak | AR2: Aerosol Concentration To P-Trak | AS2: Aerosol Conteration to DustTrak | AT2: secondary agign thermal precip duration | AU2: Mass Loss | AV2: ISS Obscuration (volts) | AW2: ISS Detector Scatter (volts) | AX2: STS Detector (volts) | AY2: STS Detector offset (volts) | AZ2: Ion A (volts) | BA2: Ion A offset V0 (volts) | BB2: Ion A (volts) Mpass_3rd | BC2: Ion A offset V0 Mpass (volts) | BD2: Ion B (volts) | BE2: Ion B offset V0 (volts) | BF2: Ptrak (PT/cc) | BG2: DustTrak A (mg/m3) Mpass_2nd | BH2: DustTrak A (mg/m3) Mpass_2nd offset | BI2: DustTrak A (mg/m3) | BJ2: DustTrak B (mg/m3) | BK2: Ion B Delta (volts) | BL2: M0 best Diameter | BM2: M1 (mm/cm^3) | BN2: Mpass_3rd offset and dilution corrected | BO2: DustTrak A (mg/m3) Mpass_2nd offset, dilution and Gain corrected | BP2: DustTrak A calibratred and corrected for dilution (mg/m3) | BQ2: DustTrak B calibratred and corrected for dilution (mg/m3) | BR2: M1/M0 (micro-m)--CMD | BS2: Diameter of Average mass (micro-m) | BT2: MPASS 3/2 | BU2: Hatch Choate Sigma g | BV2: Hatch Choate Dg | BW2: CPC 100 nm cal, dilution corrected | BX2: CPC 600 nm cal, dilution corrected | BY2: CPC 1200 nm cal, dilution corrected | BZ2: Ion B Mment (mm/cm^3) | CA2: Ion B X | CB2: Dust Trak Cal Factor (Teom/Dusttrak) | CC2: Dust Trak Dilution factor | CD2: Particle density g/cc | CE2: Sample Temperature ( C)
A3: 2 | B3: ='SAME R Results'!A85 -> 8(4) | C3: ='SAME R Results'!B85 -> Pyrell | D3: ='SAME R Results'!C85 -> P10 | E3: ='SAME R Results'!D85 -> 48 P | F3: ='SAME R Results'!E85 -> 0 | G3: ='SAME R Results'!F85 -> 95 | H3: ='SAME R Results'!G85 -> No flow run w/ aging | I3: ='SAME R Results'!H85 -> 250 | ... K3: ='SAME R Results'!J85 -> 0 | N3: ='SAME R Results'!K85 -> 0 | O3: ='SAME R Results'!L85 -> 1.22 | P3: ='SAME R Results'!M85 -> 60 | Q3: ='SAME R Results'!N85 -> 11 | R3: ='SAME R Results'!O85 -> 8 | S3: ='SAME R Results'!P85 -> n | T3: ='SAME R Results'!Q85 -> N | U3: ='SAME R Results'!R85 -> 38 | ... AB3: ='SAME R Results'!Y85 -> y | AD3: ='SAME R Results'!Z85 -> y | AE3: ='SAME R Results'!AA85 -> 10 | AF3: ='SAME R Results'!AB85 -> y | AG3: ='SAME R Results'!AC85 -> 0.038527069 | AH3: ='SAME R Results'!AD85 -> 0 | AI3: ='SAME R Results'!AE85 -> 58 | AJ3: ='SAME R Results'!AF85 -> 480 | AK3: ='SAME R Results'!AG85 -> 0 | ... AT3: ='SAME R Results'!AP85 -> 0 | AV3: ='SAME R Results'!AQ85 -> 0 | AW3: ='SAME R Results'!AR85 -> 4.819809 | AX3: ='SAME R Results'!AS85 -> 0 | AY3: ='SAME R Results'!AT85 -> 0 | BB3: ='SAME R Results'!AU85 -> 0.16464244 | BC3: ='SAME R Results'!AV85 -> 0.02626039 | BD3: ='SAME R Results'!AW85 -> 4.7402505 | BE3: ='SAME R Results'!AX85 -> 4.679245 | BF3: ='SAME R Results'!AY85 -> 1985 | BG3: ='SAME R Results'!AZ85 -> 0.2619782 | BH3: ='SAME R Results'!BA85 -> 0.07551575 | BJ3: ='SAME R Results'!BB85 -> 9.1852 | BK3: ='SAME R Results'!BC85 -> 0.0610055 | BL3: ='SAME R Results'!BD85 -> 71387.637 | BM3: ='SAME R Results'!BE85 -> 9.9926825 | BN3: ='SAME R Results'!BF85 -> 0.37536621 | BO3: ='SAME R Results'!BG85 -> 0.1264465 | BQ3: ='SAME R Results'!BH85 -> 11.899025 | BR3: ='SAME R Results'!BI85 -> 0.13997777 | BS3: ='SAME R Results'!BJ85 -> 0.68280483 | BT3: ='SAME R Results'!BL85 -> 2.9685773 | BU3: ='SAME R Results'!BM85 -> 3.5214005 | BV3: ='SAME R Results'!BN85 -> 0.063378262 | BW3: ='SAME R Results'!BO85 -> 71387.637 | BX3: ='SAME R Results'!BP85 -> 70202.626 | BY3: ='SAME R Results'!BQ85 -> 67024.478 | BZ3: ='SAME R Results'!BR85 -> 9.9926825 | CA3: ='SAME R Results'!BS85 -> 0.01354113 | CB3: ='SAME R Results'!BT85 -> 0.48 | CC3: ='SAME R Results'!BV85 -> 2.6988673 | CD3: ='SAME R Results'!BW85 -> 1 | CE3: ='SAME R Results'!BZ85 -> 236.14679
A4: 2 | B4: ='SAME R Results'!A91 -> 9(4) | C4: ='SAME R Results'!B91 -> Pyrell | D4: ='SAME R Results'!C91 -> P11 | E4: ='SAME R Results'!D91 -> 50 P | F4: ='SAME R Results'!E91 -> 0 | G4: ='SAME R Results'!F91 -> 97 | H4: ='SAME R Results'!G91 -> No flow run w/ aging | I4: ='SAME R Results'!H91 -> 251 | ... K4: ='SAME R Results'!J91 -> 0 | N4: ='SAME R Results'!K91 -> 0 | O4: ='SAME R Results'!L91 -> 1.23 | P4: ='SAME R Results'!M91 -> 60 | Q4: ='SAME R Results'!N91 -> 11 | R4: ='SAME R Results'!O91 -> 8 | S4: ='SAME R Results'!P91 -> n | T4: ='SAME R Results'!Q91 -> N | U4: ='SAME R Results'!R91 -> 48.142857 | ... AB4: ='SAME R Results'!Y91 -> y | AD4: ='SAME R Results'!Z91 -> y | AE4: ='SAME R Results'!AA91 -> 10 | AF4: ='SAME R Results'!AB91 -> y | AG4: ='SAME R Results'!AC91 -> 0.038527069 | AH4: ='SAME R Results'!AD91 -> 0 | AI4: ='SAME R Results'!AE91 -> 58 | AJ4: ='SAME R Results'!AF91 -> 480 | AK4: ='SAME R Results'!AG91 -> 0 | ... AT4: ='SAME R Results'!AP91 -> 0 | AV4: ='SAME R Results'!AQ91 -> 0 | AW4: ='SAME R Results'!AR91 -> 5.575013 | AX4: ='SAME R Results'!AS91 -> 0 | AY4: ='SAME R Results'!AT91 -> 0 | BB4: ='SAME R Results'!AU91 -> 0.1555023 | BC4: ='SAME R Results'!AV91 -> 0.02824403 | BD4: ='SAME R Results'!AW91 -> 4.758132 | BE4: ='SAME R Results'!AX91 -> 4.6959835 | BF4: ='SAME R Results'!AY91 -> 1175.5 | BG4: ='SAME R Results'!AZ91 -> 0.291397 | BH4: ='SAME R Results'!BA91 -> 0.088974025 | BJ4: ='SAME R Results'!BB91 -> 12.94395 | BK4: ='SAME R Results'!BC91 -> 0.0621485 | BL4: ='SAME R Results'!BD91 -> 42225.75 | BM4: ='SAME R Results'!BE91 -> 10.181224 | BN4: ='SAME R Results'!BF91 -> 0.34367639 | BO4: ='SAME R Results'!BG91 -> 0.13666695 | BQ4: ='SAME R Results'!BH91 -> 16.695256 | BR4: ='SAME R Results'!BI91 -> 0.2411141 | BS4: ='SAME R Results'!BJ91 -> 0.91062387 | BT4: ='SAME R Results'!BL91 -> 2.5147001 | BU4: ='SAME R Results'!BM91 -> 3.1669271 | BV4: ='SAME R Results'!BN91 -> 0.12406932 | BW4: ='SAME R Results'!BO91 -> 42225.75 | BX4: ='SAME R Results'!BP91 -> 41523.997 | BY4: ='SAME R Results'!BQ91 -> 39666.623 | BZ4: ='SAME R Results'!BR91 -> 10.181224 | CA4: ='SAME R Results'!BS91 -> 0.013794837 | CB4: ='SAME R Results'!BT91 -> 0.48 | CC4: ='SAME R Results'!BV91 -> 2.6871074 | CD4: ='SAME R Results'!BW91 -> 1 | CE4: ='SAME R Results'!BZ91 -> 242.39388
A5: 2 | B5: ='SAME R Results'!A112 -> 10 (4) | C5: ='SAME R Results'!B112 -> Pyrell | D5: ='SAME R Results'!C112 -> P12 | E5: ='SAME R Results'!D112 -> 60 P | F5: ='SAME R Results'!E112 -> 0 | G5: ='SAME R Results'!F112 -> 107 | H5: ='SAME R Results'!G112 -> Low flow run w/ aging | I5: ='SAME R Results'!H112 -> 252 | ... K5: ='SAME R Results'!J112 -> 0 | N5: ='SAME R Results'!K112 -> 1 | O5: ='SAME R Results'!L112 -> 1.23 | P5: ='SAME R Results'!M112 -> 60 | Q5: ='SAME R Results'!N112 -> 11 | R5: ='SAME R Results'!O112 -> 8 | S5: ='SAME R Results'!P112 -> n | T5: ='SAME R Results'!Q112 -> N | U5: ='SAME R Results'!R112 -> 32 | ... AB5: ='SAME R Results'!Y112 -> y | AD5: ='SAME R Results'!Z112 -> y | AE5: ='SAME R Results'!AA112 -> 10 | AF5: ='SAME R Results'!AB112 -> y | AG5: ='SAME R Results'!AC112 -> 0.038527069 | AH5: ='SAME R Results'!AD112 -> 0 | AI5: ='SAME R Results'!AE112 -> 58 | AJ5: ='SAME R Results'!AF112 -> 480 | AK5: ='SAME R Results'!AG112 -> 0 | ... AT5: ='SAME R Results'!AP112 -> 0 | AV5: ='SAME R Results'!AQ112 -> 0 | AW5: ='SAME R Results'!AR112 -> 6.2564995 | AX5: ='SAME R Results'!AS112 -> 0 | AY5: ='SAME R Results'!AT112 -> 0 | BB5: ='SAME R Results'!AU112 -> 1.0387568 | BC5: ='SAME R Results'!AV112 -> 0.04818725 | BD5: ='SAME R Results'!AW112 -> 4.990799 | BE5: ='SAME R Results'!AX112 -> 4.67427 | BF5: ='SAME R Results'!AY112 -> 5698 | BG5: ='SAME R Results'!AZ112 -> 1.27539 | BH5: ='SAME R Results'!BA112 -> 0.095474235 | BJ5: ='SAME R Results'!BB112 -> 68.19105 | BK5: ='SAME R Results'!BC112 -> 0.316529 | BL5: ='SAME R Results'!BD112 -> 206018.56 | BM5: ='SAME R Results'!BE112 -> 53.439569 | BN5: ='SAME R Results'!BF112 -> 2.5745938 | BO5: ='SAME R Results'!BG112 -> 0.76668107 | BQ5: ='SAME R Results'!BH112 -> 84.672704 | BR5: ='SAME R Results'!BI112 -> 0.25939202 | BS5: ='SAME R Results'!BJ112 -> 0.92245705 | BT5: ='SAME R Results'!BL112 -> 3.3581028 | BU5: ='SAME R Results'!BM112 -> 3.0844272 | BV5: ='SAME R Results'!BN112 -> 0.13755039 | BW5: ='SAME R Results'!BO112 -> 206018.56 | BX5: ='SAME R Results'!BP112 -> 202616.95 | BY5: ='SAME R Results'!BQ112 -> 192944.84 | BZ5: ='SAME R Results'!BR112 -> 53.439569 | CA5: ='SAME R Results'!BS112 -> 0.07025859 | CB5: ='SAME R Results'!BT112 -> 0.48 | CC5: ='SAME R Results'!BV112 -> 2.5868712 | CD5: ='SAME R Results'!BW112 -> 1 | CE5: ='SAME R Results'!BZ112 -> 245.4141
A6: 2 | B6: ='SAME R Results'!A121 -> 11(4) | C6: ='SAME R Results'!B121 -> Pyrell | D6: ='SAME R Results'!C121 -> P13 | E6: ='SAME R Results'!D121 -> 66 P | F6: ='SAME R Results'!E121 -> 0 | G6: ='SAME R Results'!F121 -> 113 | H6: ='SAME R Results'!G121 -> low flow run w STS | I6: ='SAME R Results'!H121 -> 253 | ... K6: ='SAME R Results'!J121 -> 0 | N6: ='SAME R Results'!K121 -> 2 | O6: ='SAME R Results'!L121 -> 1.23 | P6: ='SAME R Results'!M121 -> 60 | Q6: ='SAME R Results'!N121 -> 11 | R6: ='SAME R Results'!O121 -> 8 | S6: ='SAME R Results'!P121 -> n | T6: ='SAME R Results'!Q121 -> n | U6: ='SAME R Results'!R121 -> 31 | ... AB6: ='SAME R Results'!Y121 -> y | AD6: ='SAME R Results'!Z121 -> y | AE6: ='SAME R Results'!AA121 -> 10 | AF6: ='SAME R Results'!AB121 -> y | AG6: ='SAME R Results'!AC121 -> 0.038527069 | AH6: ='SAME R Results'!AD121 -> 0 | AI6: ='SAME R Results'!AE121 -> 0 | AJ6: ='SAME R Results'!AF121 -> 0 | AK6: ='SAME R Results'!AG121 -> 0 | ... AT6: ='SAME R Results'!AP121 -> 0 | AV6: ='SAME R Results'!AQ121 -> 0 | AW6: ='SAME R Results'!AR121 -> 6.283677 | AX6: ='SAME R Results'!AS121 -> 4.6147465 | AY6: ='SAME R Results'!AT121 -> 5.155837 | BB6: ='SAME R Results'!AU121 -> 0 | BC6: ='SAME R Results'!AV121 -> 0 | BD6: ='SAME R Results'!AW121 -> 6.718872 | BE6: ='SAME R Results'!AX121 -> 4.705779 | BF6: ='SAME R Results'!AY121 -> 31375 | BG6: ='SAME R Results'!AZ121 -> 0 | BH6: ='SAME R Results'!BA121 -> 0 | BJ6: ='SAME R Results'!BB121 -> 154.35555 | BK6: ='SAME R Results'!BC121 -> 2.013093 | BL6: ='SAME R Results'!BD121 -> 1176224.5 | BM6: ='SAME R Results'!BE121 -> 459.76995 | BN6: ='SAME R Results'!BF121 -> 0 | BO6: ='SAME R Results'!BG121 -> 0 | BQ6: ='SAME R Results'!BH121 -> 169.19488 | BR6: ='SAME R Results'!BI121 -> 0.39088624 | BS6: ='SAME R Results'!BJ121 -> 0.65007899 | BT6: ='SAME R Results'!BL121 -> 0 | BU6: ='SAME R Results'!BM121 -> 2.0405435 | BV6: ='SAME R Results'!BN121 -> 0.30310458 | BW6: ='SAME R Results'!BO121 -> 1176224.5 | BX6: ='SAME R Results'!BP121 -> 1157494.1 | BY6: ='SAME R Results'!BQ121 -> 1083326.1 | BZ6: ='SAME R Results'!BR121 -> 459.76995 | CA6: ='SAME R Results'!BS121 -> 0.44683765 | CB6: ='SAME R Results'!BT121 -> 0.48 | CC6: ='SAME R Results'!BV121 -> 2.2836194 | CD6: ='SAME R Results'!BW121 -> 1 | CE6: ='SAME R Results'!BZ121 -> 245.37088
