Workbook

Sheet Smoke Point Datasheet
A1: Master Sheets of ISS Tests for SPICE
AO2: 1500 | AR2: Peter's 2nd Attempt
A3: GMT | B3: GMT | C3: GMT | D3: GMT | E3: No. | F3: TP | G3: Fuel | H3: Nozzle | I3: Pressure | J3: MWmix | K3: MWf | L3: Xf | M3: Fuel | N3: Air | O3: Fan | P3: Rad | Q3: Gain | R3: Pixel | S3: smk pt | T3: Pixel | U3: flame w | V3: HC Density | W3: Tad | X3: Viscosity | Y3: Net K. Viscosity | Z3: Total Fuel Rate | AA3: HC Only Rate | AB3: mdotburner | AC3: mdotHC | AD3: uair | AE3: ufuel | AF3: 2 ufuel | AG3: uair/2ufuel | AH3: Re | AI3: Re | AJ3: Re | AK3: Re/Zst | AL3: Re/Zst | AM3: mf/Zst | AN3: SH/d | AO3: visc-air,Roper | AQ3: uf/air | AR3: Iu | AS3: z0 | AT3: Tres | AU3: Tres(reduced) | AX3: Tform | AY3: Toxid | AZ3: Tform/Toxid
A4: date | B4: ignite | C4: flame off | D4: data | F4: # | H4: (mm) | I4: (Pa) | J4: g/mol | K4: g/mol | M4: Display | N4: Display | R4: length | S4: mm | T4: width | U4: mm | V4: g/m^3 | W4: K | X4: m/g-s | Y4: m^2/s | Z4: sccm | AA4: sccm | AB4: (mg/s) | AC4: (mg/s) | AD4: (cm/s) | AE4: (cm/s) | AF4: (cm/s) | AH4: (Air Viscosity) | AI4: (Amb. Air Visc.) | AJ4: (Fuel Viscosity) | AK4: (Air Viscosity) | AL4: (Amb. Air Visc.) | AO4: m2/s | AR4: m^2/s | AS4: m | AT4: ms | AU4: ms | AX4: ms | AY4: ms | BF4: u_a/2u_f | BG4: u_a/u_f | BH4: SP | BI4: mf/Zst
A5: 45 | B5: 0.6252662 | C5: 0.62822917 | D5: 0.62725694 | E5: 3 | F5: E16-1 | G5: Ethylene | H5: 1.6002 | I5: 101325 | J5: 28.05 | K5: 28.05 | L5: 1 | M5: 285 | N5: 68 | O5: 141 | P5: 4.1 | R5: 193 | S5: =R5*Reference!$B$23+Reference!$B$24 -> 75.354799 | T5: 28 | U5: =T5*-Reference!$B$23 -> 6.4326677 | V5: =Reference!$L$20 -> 1162.2987 | W5: 2367.4 | X5: =Reference!$W$20 -> 0.050086 | Y5: =(20*10^-6)*(600/298)^(1.67) -> 6.4357835e-05 | Z5: =M5*Reference!$L$5 -> 171 | AA5: =Z5 -> 171 | AB5: =Z5*Reference!$L$20/(60*10^3) -> 3.3125514 | AC5: =AB5 -> 3.3125514 | AD5: =N5*Reference!$F$10+Reference!$F$11 -> 58.016277 | AE5: =(Z5/(PI()/4*((H5/10)^2)*60)) -> 141.71194 | AF5: =AE5*2 -> 283.42388 | AG5: =AD5/(2*AE5) -> 0.20469791 | AH5: =(AE5/100)*Reference!$L$20*(H5/1000)/(Reference!$W$20) -> 52.623791 | AI5: =(AE5/100)*Reference!$L$20*(H5/1000)/(Reference!$P$26) -> 140.19762 | AJ5: =(AE5/100)*Reference!$L$20*(H5/1000)/(Reference!$P$20) -> 257.55545 | AK5: =AH5/(Reference!$R$20) -> 825.76916 | AL5: =AI5/(Reference!$R$20) -> 2199.972 | AM5: =AB5/(Reference!$R$20) -> 51.980345 | AN5: =S5/H5 -> 47.090863 | AO5: =0.00002*(AO$2/293)^1.67 -> 0.00030579718 | AQ5: =AE5/AD5 -> 2.4426239 | AR5: =(1/0.0557)*(H5/1000)^2*V5*(AE5/100)/6*((AE5/100)-(AD5/100)*0.75) -> 0.012393005 | AS5: =0.75*AR5/(2*(AE5/100)-(AD5/100)) -> 0.0041235314 | AT5: =1000*(S5/1000)/(AD5/100)-(0.75*AR5/(AD5/100)^2)*LN(ABS(1+((AD5/100)*(S5/1000)/(0.75*AR5))*(1-((AD5/100)/(2*(AE5/100)))))) -> 129.84264 | AU5: =1/(AD5/100)*LN((4*AD5/100*(S5/1000+AS5)+3*AR5)/(4*AD5/100*AS5+3*AR5)) -> 2.6823312 | AV5: =1/(AD5/100)*LN((4*AD5/100*(S5/2000+AS5)+3*AR5)/(4*AD5/100*AS5+3*AR5)) -> 1.8174851 | AW5: =AU5-AV5 -> 0.8648461 | AX5: =1000*(S5/2000)/(AD5/100)-(0.75*AR5/(AD5/100)^2)*LN(ABS(1+((AD5/100)*(S5/2000)/(0.75*AR5))*(1-((AD5/100)/(2*(AE5/100)))))) -> 64.913691 | AY5: =AT5-AX5 -> 64.928953 | AZ5: =AX5/AY5 -> 0.99976494 | BD5: 75.354799 | BE5: 0.20469791 | BF5: 0.20469791 | BG5: =BF5*2 -> 0.40939582 | BH5: 75.354799 | BI5: 51.980345
A6: 45 | B6: 0.60912037 | C6: 0.61670139 | D6: 0.60967593 | E6: 1 | F6: E16-2 | G6: Ethylene | H6: 1.6002 | I6: 101325 | J6: 28.05 | K6: 28.05 | L6: 1 | M6: 207 | N6: 42 | O6: 99 | P6: 0.28 | R6: 286 | S6: =R6*Reference!$B$23+Reference!$B$24 -> 53.989152 | T6: 26 | U6: =T6*-Reference!$B$23 -> 5.9731915 | V6: =Reference!$L$20 -> 1162.2987 | W6: 2367.4 | X6: =Reference!$W$20 -> 0.050086 | Y6: =(20*10^-6)*(600/298)^(1.67) -> 6.4357835e-05 | Z6: =M6*Reference!$L$5 -> 124.2 | AA6: =Z6 -> 124.2 | AB6: =Z6*Reference!$L$20/(60*10^3) -> 2.4059584 | AC6: =AB6 -> 2.4059584 | AD6: =N6*Reference!$F$10+Reference!$F$11 -> 33.570677 | AE6: =(Z6/(PI()/4*((H6/10)^2)*60)) -> 102.92762 | AF6: =AE6*2 -> 205.85524 | AG6: =AD6/(2*AE6) -> 0.16307905 | AH6: =(AE6/100)*Reference!$L$20*(H6/1000)/(Reference!$W$20) -> 38.22149 | AI6: =(AE6/100)*Reference!$L$20*(H6/1000)/(Reference!$P$26) -> 101.82774 | AJ6: =(AE6/100)*Reference!$L$20*(H6/1000)/(Reference!$P$20) -> 187.06659 | AK6: =AH6/(Reference!$R$20) -> 599.76918 | AL6: =AI6/(Reference!$R$20) -> 1597.8744 | AM6: =AB6/(Reference!$R$20) -> 37.754145 | AN6: =S6/H6 -> 33.739003 | AO6: =0.00002*(AO$2/293)^1.67 -> 0.00030579718 | AQ6: =AE6/AD6 -> 3.0659978 | AR6: =(1/0.0557)*(H6/1000)^2*V6*(AE6/100)/6*((AE6/100)-(AD6/100)*0.75) -> 0.0071267253 | AS6: =0.75*AR6/(2*(AE6/100)-(AD6/100)) -> 0.0031024509 | AT6: =1000*(S6/1000)/(AD6/100)-(0.75*AR6/(AD6/100)^2)*LN(ABS(1+((AD6/100)*(S6/1000)/(0.75*AR6))*(1-((AD6/100)/(2*(AE6/100)))))) -> 160.75857 | AU6: =1/(AD6/100)*LN((4*AD6/100*(S6/1000+AS6)+3*AR6)/(4*AD6/100*AS6+3*AR6)) -> 4.0062639 | AV6: =1/(AD6/100)*LN((4*AD6/100*(S6/2000+AS6)+3*AR6)/(4*AD6/100*AS6+3*AR6)) -> 2.631276 | AW6: =AU6-AV6 -> 1.3749878 | AX6: =1000*(S6/2000)/(AD6/100)-(0.75*AR6/(AD6/100)^2)*LN(ABS(1+((AD6/100)*(S6/2000)/(0.75*AR6))*(1-((AD6/100)/(2*(AE6/100)))))) -> 80.369282 | AY6: =AT6-AX6 -> 80.389285 | AZ6: =AX6/AY6 -> 0.99975118 | BD6: 53.989152 | BE6: 0.16307905 | BF6: 0.16307905 | BG6: =BF6*2 -> 0.32615809 | BH6: 53.989152 | BI6: 37.754145
A7: 45 | B7: 0.61813657 | C7: 0.61957176 | D7: 0.61842593 | F7: E16-3 | G7: Ethylene | H7: 1.6002 | I7: 101325 | J7: 28.05 | K7: 28.05 | L7: 1 | M7: 211 | N7: 48 | O7: 48 | P7: 100 | R7: 278 | S7: =R7*Reference!$B$23+Reference!$B$24 -> 55.827057 | T7: 28 | U7: =T7*-Reference!$B$23 -> 6.4326677 | V7: =Reference!$L$20 -> 1162.2987 | W7: 2367.4 | X7: =Reference!$W$20 -> 0.050086 | Y7: =(20*10^-6)*(600/298)^(1.67) -> 6.4357835e-05 | Z7: =M7*Reference!$L$5 -> 126.6 | AA7: =Z7 -> 126.6 | AB7: =Z7*Reference!$L$20/(60*10^3) -> 2.4524503 | AC7: =AB7 -> 2.4524503 | AD7: =N7*Reference!$F$10+Reference!$F$11 -> 39.211969 | AE7: =(Z7/(PI()/4*((H7/10)^2)*60)) -> 104.91656 | AF7: =AE7*2 -> 209.83312 | AG7: =AD7/(2*AE7) -> 0.18687216 | AH7: =(AE7/100)*Reference!$L$20*(H7/1000)/(Reference!$W$20) -> 38.96007 | AI7: =(AE7/100)*Reference!$L$20*(H7/1000)/(Reference!$P$26) -> 103.79543 | AJ7: =(AE7/100)*Reference!$L$20*(H7/1000)/(Reference!$P$20) -> 190.68141 | AK7: =AH7/(Reference!$R$20) -> 611.35892 | AL7: =AI7/(Reference!$R$20) -> 1628.7512 | AM7: =AB7/(Reference!$R$20) -> 38.483694 | AN7: =S7/H7 -> 34.88755 | AO7: =0.00002*(AO$2/293)^1.67 -> 0.00030579718 | AQ7: =AE7/AD7 -> 2.6756259 | AR7: =(1/0.0557)*(H7/1000)^2*V7*(AE7/100)/6*((AE7/100)-(AD7/100)*0.75) -> 0.0070549585 | AS7: =0.75*AR7/(2*(AE7/100)-(AD7/100)) -> 0.0031011506 | AT7: =1000*(S7/1000)/(AD7/100)-(0.75*AR7/(AD7/100)^2)*LN(ABS(1+((AD7/100)*(S7/1000)/(0.75*AR7))*(1-((AD7/100)/(2*(AE7/100)))))) -> 142.32179 | AU7: =1/(AD7/100)*LN((4*AD7/100*(S7/1000+AS7)+3*AR7)/(4*AD7/100*AS7+3*AR7)) -> 3.7575458 | AV7: =1/(AD7/100)*LN((4*AD7/100*(S7/2000+AS7)+3*AR7)/(4*AD7/100*AS7+3*AR7)) -> 2.5160123 | AW7: =AU7-AV7 -> 1.2415336 | AX7: =1000*(S7/2000)/(AD7/100)-(0.75*AR7/(AD7/100)^2)*LN(ABS(1+((AD7/100)*(S7/2000)/(0.75*AR7))*(1-((AD7/100)/(2*(AE7/100)))))) -> 71.152295 | AY7: =AT7-AX7 -> 71.169493 | AZ7: =AX7/AY7 -> 0.99975836 | BD7: 55.827057 | BE7: 0.18687216 | BF7: 0.18687216 | BG7: =BF7*2 -> 0.37374433 | BH7: 55.827057 | BI7: 38.483694
A8: 168 | B8: 0.40917824 | C8: 0.41018519 | D8: 0.4100463 | F8: E16-4 | G8: Ethylene | H8: 1.6002 | I8: 101325 | J8: 28.05 | K8: 28.05 | L8: 1 | M8: 209 | N8: 45 | O8: 96 | P8: 0.17361111 | Q8: 250 | R8: 271 | S8: =R8*Reference!$R$60+Reference!$R$61 -> 57.504494 | T8: 31 | U8: =T8*-Reference!$R$60 -> 7.1228728 | V8: =Reference!$L$20 -> 1162.2987 | W8: 2367.4 | X8: =Reference!$W$20 -> 0.050086 | Y8: =(20*10^-6)*(600/298)^(1.67) -> 6.4357835e-05 | Z8: =M8*Reference!$L$5 -> 125.4 | AA8: =Z8 -> 125.4 | AB8: =Z8*Reference!$L$20/(60*10^3) -> 2.4292044 | AC8: =AB8 -> 2.4292044 | AD8: =N8*Reference!$F$10+Reference!$F$11 -> 36.391323 | AE8: =(Z8/(PI()/4*((H8/10)^2)*60)) -> 103.92209 | AF8: =AE8*2 -> 207.84418 | AG8: =AD8/(2*AE8) -> 0.17508945 | AH8: =(AE8/100)*Reference!$L$20*(H8/1000)/(Reference!$W$20) -> 38.59078 | AI8: =(AE8/100)*Reference!$L$20*(H8/1000)/(Reference!$P$26) -> 102.81159 | AJ8: =(AE8/100)*Reference!$L$20*(H8/1000)/(Reference!$P$20) -> 188.874 | AK8: =AH8/(Reference!$R$20) -> 605.56405 | AL8: =AI8/(Reference!$R$20) -> 1613.3128 | AM8: =AB8/(Reference!$R$20) -> 38.118919 | AN8: =S8/H8 -> 35.935817 | AO8: =0.00002*(AO$2/293)^1.67 -> 0.00030579718 | AQ8: =AE8/AD8 -> 2.8556832 | AR8: =(1/0.0557)*(H8/1000)^2*V8*(AE8/100)/6*((AE8/100)-(AD8/100)*0.75) -> 0.0070918347 | AS8: =0.75*AR8/(2*(AE8/100)-(AD8/100)) -> 0.0031022382 | AT8: =1000*(S8/1000)/(AD8/100)-(0.75*AR8/(AD8/100)^2)*LN(ABS(1+((AD8/100)*(S8/1000)/(0.75*AR8))*(1-((AD8/100)/(2*(AE8/100)))))) -> 157.95898 | AU8: =1/(AD8/100)*LN((4*AD8/100*(S8/1000+AS8)+3*AR8)/(4*AD8/100*AS8+3*AR8)) -> 3.9731131 | AV8: =1/(AD8/100)*LN((4*AD8/100*(S8/2000+AS8)+3*AR8)/(4*AD8/100*AS8+3*AR8)) -> 2.6496166 | AW8: =AU8-AV8 -> 1.3234965 | AX8: =1000*(S8/2000)/(AD8/100)-(0.75*AR8/(AD8/100)^2)*LN(ABS(1+((AD8/100)*(S8/2000)/(0.75*AR8))*(1-((AD8/100)/(2*(AE8/100)))))) -> 78.969798 | AY8: =AT8-AX8 -> 78.98918 | AZ8: =AX8/AY8 -> 0.99975462 | BD8: 57.504494 | BE8: 0.17508945 | BF8: 0.17508945 | BG8: =BF8*2 -> 0.3501789 | BH8: 57.504494 | BI8: 38.118919
A9: 45 | B9: 0.65878472 | C9: 0.65924769 | D9: 0.65887731 | E9: 5 | F9: E16-5 | G9: Ethylene | H9: 1.6002 | I9: 101325 | J9: 28.05 | K9: 28.05 | L9: 1 | M9: 140 | N9: 26 | O9: 65 | P9: 4.1 | R9: 360 | S9: =R9*Reference!$B$23+Reference!$B$24 -> 36.98853 | T9: 25 | U9: =T9*-Reference!$B$23 -> 5.7434533 | V9: =Reference!$L$20 -> 1162.2987 | W9: 2367.4 | X9: =Reference!$W$20 -> 0.050086 | Y9: =(20*10^-6)*(600/298)^(1.67) -> 6.4357835e-05 | Z9: =M9*Reference!$L$5 -> 84 | AA9: =Z9 -> 84 | AB9: =Z9*Reference!$L$20/(60*10^3) -> 1.6272182 | AC9: =AB9 -> 1.6272182 | AD9: =N9*Reference!$F$10+Reference!$F$11 -> 18.52723 | AE9: =(Z9/(PI()/4*((H9/10)^2)*60)) -> 69.612883 | AF9: =AE9*2 -> 139.22577 | AG9: =AD9/(2*AE9) -> 0.13307329 | AH9: =(AE9/100)*Reference!$L$20*(H9/1000)/(Reference!$W$20) -> 25.850283 | AI9: =(AE9/100)*Reference!$L$20*(H9/1000)/(Reference!$P$26) -> 68.869005 | AJ9: =(AE9/100)*Reference!$L$20*(H9/1000)/(Reference!$P$20) -> 126.51847 | AK9: =AH9/(Reference!$R$20) -> 405.64099 | AL9: =AI9/(Reference!$R$20) -> 1080.688 | AM9: =AB9/(Reference!$R$20) -> 25.534204 | AN9: =S9/H9 -> 23.114942 | AO9: =0.00002*(AO$2/293)^1.67 -> 0.00030579718 | AQ9: =AE9/AD9 -> 3.7573281 | AR9: =(1/0.0557)*(H9/1000)^2*V9*(AE9/100)/6*((AE9/100)-(AD9/100)*0.75) -> 0.0034541468 | AS9: =0.75*AR9/(2*(AE9/100)-(AD9/100)) -> 0.0021463476 | AT9: =1000*(S9/1000)/(AD9/100)-(0.75*AR9/(AD9/100)^2)*LN(ABS(1+((AD9/100)*(S9/1000)/(0.75*AR9))*(1-((AD9/100)/(2*(AE9/100)))))) -> 199.55419 | AU9: =1/(AD9/100)*LN((4*AD9/100*(S9/1000+AS9)+3*AR9)/(4*AD9/100*AS9+3*AR9)) -> 6.4331545 | AV9: =1/(AD9/100)*LN((4*AD9/100*(S9/2000+AS9)+3*AR9)/(4*AD9/100*AS9+3*AR9)) -> 4.1231465 | AW9: =AU9-AV9 -> 2.310008 | AX9: =1000*(S9/2000)/(AD9/100)-(0.75*AR9/(AD9/100)^2)*LN(ABS(1+((AD9/100)*(S9/2000)/(0.75*AR9))*(1-((AD9/100)/(2*(AE9/100)))))) -> 99.764419 | AY9: =AT9-AX9 -> 99.789771 | AZ9: =AX9/AY9 -> 0.99974594 | BD9: 36.98853 | BE9: 0.13307329 | BF9: 0.13307329 | BG9: =BF9*2 -> 0.26614657 | BH9: 36.98853 | BI9: 25.534204
A10: 45 | B10: 0.72763889 | C10: 0.72802083 | D10: 0.72811343 | F10: E7-1 | G10: Ethylene | H10: 0.762 | I10: 101325 | J10: 28.05 | K10: 28.05 | L10: 1 | M10: 335 | N10: 25 | O10: 66 | P10: 4.1 | Q10: 250 | R10: 63 | S10: =R10*Reference!$B$23+Reference!$B$24 -> 105.22076 | T10: 27 | U10: =T10*-Reference!$B$23 -> 6.2029296 | V10: =Reference!$L$20 -> 1162.2987 | W10: 2367.4 | X10: =Reference!$W$20 -> 0.050086 | Y10: =(20*10^-6)*(600/298)^(1.67) -> 6.4357835e-05 | Z10: =M10*Reference!$L$5 -> 201 | AA10: =Z10 -> 201 | AB10: =Z10*Reference!$L$20/(60*10^3) -> 3.8937008 | AC10: =AB10 -> 3.8937008 | AD10: =N10*Reference!$F$10+Reference!$F$11 -> 17.587015 | AE10: =(Z10/(PI()/4*((H10/10)^2)*60)) -> 734.58995 | AF10: =AE10*2 -> 1469.1799 | AG10: =AD10/(2*AE10) -> 0.011970634 | AH10: =(AE10/100)*Reference!$L$20*(H10/1000)/(Reference!$W$20) -> 129.89767 | AI10: =(AE10/100)*Reference!$L$20*(H10/1000)/(Reference!$P$26) -> 346.06675 | AJ10: =(AE10/100)*Reference!$L$20*(H10/1000)/(Reference!$P$20) -> 635.7553 | AK10: =AH10/(Reference!$R$20) -> 2038.346 | AL10: =AI10/(Reference!$R$20) -> 5430.4572 | AM10: =AB10/(Reference!$R$20) -> 61.099703 | AN10: =S10/H10 -> 138.08498 | AO10: =0.00002*(AO$2/293)^1.67 -> 0.00030579718 | AQ10: =AE10/AD10 -> 41.768882 | AR10: =(1/0.0557)*(H10/1000)^2*V10*(AE10/100)/6*((AE10/100)-(AD10/100)*0.75) -> 0.10701439 | AS10: =0.75*AR10/(2*(AE10/100)-(AD10/100)) -> 0.0055291533 | AT10: =1000*(S10/1000)/(AD10/100)-(0.75*AR10/(AD10/100)^2)*LN(ABS(1+((AD10/100)*(S10/1000)/(0.75*AR10))*(1-((AD10/100)/(2*(AE10/100)))))) -> 597.75407 | AU10: =1/(AD10/100)*LN((4*AD10/100*(S10/1000+AS10)+3*AR10)/(4*AD10/100*AS10+3*AR10)) -> 1.1669212 | AV10: =1/(AD10/100)*LN((4*AD10/100*(S10/2000+AS10)+3*AR10)/(4*AD10/100*AS10+3*AR10)) -> 0.61334363 | AW10: =AU10-AV10 -> 0.55357758 | AX10: =1000*(S10/2000)/(AD10/100)-(0.75*AR10/(AD10/100)^2)*LN(ABS(1+((AD10/100)*(S10/2000)/(0.75*AR10))*(1-((AD10/100)/(2*(AE10/100)))))) -> 298.8634 | AY10: =AT10-AX10 -> 298.89067 | AZ10: =AX10/AY10 -> 0.99990875 | BD10: 105.22076 | BE10: 0.011970634
A11: 48 | B11: 0.70399306 | C11: 0.70496528 | D11: 0.70447917 | E11: 19 | F11: P16-1 | G11: Propane | H11: 1.6002 | I11: 101325 | J11: 44.1 | K11: 44.1 | L11: 1 | M11: 276 | N11: 54 | O11: 100 | P11: 1.73 | R11: 216 | S11: =R11*Reference!$B$42+Reference!$B$43 -> 71.383568 | T11: 29 | U11: =T11*-Reference!$B$42 -> 6.7649833 | V11: =Reference!$L$21 -> 1826.8482 | W11: 2264.12 | X11: =Reference!$W$21 -> 0.048845 | Y11: =(20*10^-6)*(600/298)^(1.67) -> 6.4357835e-05 | Z11: =M11*Reference!$L$6 -> 99.36 | AA11: =Z11 -> 99.36 | AB11: =Z11*Reference!$L$21/(60*10^3) -> 3.0252607 | AC11: =AB11 -> 3.0252607 | AD11: =N11*Reference!$F$10+Reference!$F$11 -> 44.853261 | AE11: =(Z11/(PI()/4*((H11/10)^2)*60)) -> 82.342096 | AF11: =AE11*2 -> 164.68419 | AG11: =AD11/(2*AE11) -> 0.27235924 | AH11: =(AE11/100)*Reference!$L$21*(H11/1000)/(Reference!$W$21) -> 49.28089 | AI11: =(AE11/100)*Reference!$L$21*(H11/1000)/(Reference!$P$26) -> 128.03857 | AJ11: =(AE11/100)*Reference!$L$21*(H11/1000)/(Reference!$P$21) -> 296.06919 | AK11: =AH11/Reference!$R$21 -> 816.98411 | AL11: =AI11/(Reference!$R$21) -> 2122.6377 | AM11: =AB11/(Reference!$R$21) -> 50.15311 | AN11: =S11/H11 -> 44.609154 | AO11: =0.00002*(AO$2/293)^1.67 -> 0.00030579718 | AQ11: =AE11/AD11 -> 1.8358107 | AR11: =(1/0.0557)*(H11/1000)^2*V11*(AE11/100)/6*((AE11/100)-(AD11/100)*0.75) -> 0.005613253 | AS11: =0.75*AR11/(2*(AE11/100)-(AD11/100)) -> 0.0035132329 | AT11: =1000*(S11/1000)/(AD11/100)-(0.75*AR11/(AD11/100)^2)*LN(ABS(1+((AD11/100)*(S11/1000)/(0.75*AR11))*(1-((AD11/100)/(2*(AE11/100)))))) -> 159.10984 | AU11: =1/(AD11/100)*LN((4*AD11/100*(S11/1000+AS11)+3*AR11)/(4*AD11/100*AS11+3*AR11)) -> 4.1847751 | AV11: =1/(AD11/100)*LN((4*AD11/100*(S11/2000+AS11)+3*AR11)/(4*AD11/100*AS11+3*AR11)) -> 2.956907 | AW11: =AU11-AV11 -> 1.2278681 | AX11: =1000*(S11/2000)/(AD11/100)-(0.75*AR11/(AD11/100)^2)*LN(ABS(1+((AD11/100)*(S11/2000)/(0.75*AR11))*(1-((AD11/100)/(2*(AE11/100)))))) -> 79.546804 | AY11: =AT11-AX11 -> 79.563032 | AZ11: =AX11/AY11 -> 0.99979603 | BD11: 71.383568 | BE11: 0.27235924 | BF11: 0.27235924 | BG11: =BF11*2 -> 0.54471848 | BH11: 71.383568 | BI11: 50.15311
A12: 48 | B12: 0.71621528 | C12: 0.71774306 | D12: 0.71675926 | E12: 21 | F12: P16-2 | G12: Propane | H12: 1.6002 | I12: 101325 | J12: 44.1 | K12: 44.1 | L12: 1 | M12: 230 | N12: 45 | O12: 85 | P12: 1.43 | R12: 260 | S12: =R12*Reference!$B$42+Reference!$B$43 -> 61.119455 | T12: 29 | U12: =T12*-Reference!$B$42 -> 6.7649833 | V12: =Reference!$L$21 -> 1826.8482 | W12: 2264.12 | X12: =Reference!$W$21 -> 0.048845 | Y12: =(20*10^-6)*(600/298)^(1.67) -> 6.4357835e-05 | Z12: =M12*Reference!$L$6 -> 82.8 | AA12: =Z12 -> 82.8 | AB12: =Z12*Reference!$L$21/(60*10^3) -> 2.5210506 | AC12: =AB12 -> 2.5210506 | AD12: =N12*Reference!$F$10+Reference!$F$11 -> 36.391323 | AE12: =(Z12/(PI()/4*((H12/10)^2)*60)) -> 68.618414 | AF12: =AE12*2 -> 137.23683 | AG12: =AD12/(2*AE12) -> 0.2651717 | AH12: =(AE12/100)*Reference!$L$21*(H12/1000)/(Reference!$W$21) -> 41.067408 | AI12: =(AE12/100)*Reference!$L$21*(H12/1000)/(Reference!$P$26) -> 106.69881 | AJ12: =(AE12/100)*Reference!$L$21*(H12/1000)/(Reference!$P$21) -> 246.72433 | AK12: =AH12/Reference!$R$21 -> 680.82009 | AL12: =AI12/(Reference!$R$21) -> 1768.8648 | AM12: =AB12/(Reference!$R$21) -> 41.794259 | AN12: =S12/H12 -> 38.194885 | AO12: =0.00002*(AO$2/293)^1.67 -> 0.00030579718 | AQ12: =AE12/AD12 -> 1.8855707 | AR12: =(1/0.0557)*(H12/1000)^2*V12*(AE12/100)/6*((AE12/100)-(AD12/100)*0.75) -> 0.0039691478 | AS12: =0.75*AR12/(2*(AE12/100)-(AD12/100)) -> 0.0029519024 | AT12: =1000*(S12/1000)/(AD12/100)-(0.75*AR12/(AD12/100)^2)*LN(ABS(1+((AD12/100)*(S12/1000)/(0.75*AR12))*(1-((AD12/100)/(2*(AE12/100)))))) -> 167.90859 | AU12: =1/(AD12/100)*LN((4*AD12/100*(S12/1000+AS12)+3*AR12)/(4*AD12/100*AS12+3*AR12)) -> 5.139482 | AV12: =1/(AD12/100)*LN((4*AD12/100*(S12/2000+AS12)+3*AR12)/(4*AD12/100*AS12+3*AR12)) -> 3.6285467 | AW12: =AU12-AV12 -> 1.5109352 | AX12: =1000*(S12/2000)/(AD12/100)-(0.75*AR12/(AD12/100)^2)*LN(ABS(1+((AD12/100)*(S12/2000)/(0.75*AR12))*(1-((AD12/100)/(2*(AE12/100)))))) -> 83.945632 | AY12: =AT12-AX12 -> 83.962955 | AZ12: =AX12/AY12 -> 0.99979369 | BD12: 61.119455 | BE12: 0.2651717 | BF12: 0.2651717 | BG12: =BF12*2 -> 0.5303434 | BH12: 61.119455 | BI12: 41.794259
A13: 48 | B13: 0.7393287 | C13: 0.74075231 | D13: 0.73978009 | E13: 23 | F13: P16-3 | G13: Propane | H13: 1.6002 | I13: 101325 | J13: 44.1 | K13: 44.1 | L13: 1 | M13: 164 | N13: 30 | O13: 65 | P13: 1 | R13: 325 | S13: =R13*Reference!$N$78+Reference!$N$79 -> 45.522586 | T13: 34 | U13: =T13*-Reference!$N$78 -> 6.8706197 | V13: =Reference!$L$21 -> 1826.8482 | W13: 2264.12 | X13: =Reference!$W$21 -> 0.048845 | Y13: =(20*10^-6)*(600/298)^(1.67) -> 6.4357835e-05 | Z13: =M13*Reference!$L$6 -> 59.04 | AA13: =Z13 -> 59.04 | AB13: =Z13*Reference!$L$21/(60*10^3) -> 1.7976187 | AC13: =AB13 -> 1.7976187 | AD13: =N13*Reference!$F$10+Reference!$F$11 -> 22.288092 | AE13: =(Z13/(PI()/4*((H13/10)^2)*60)) -> 48.927912 | AF13: =AE13*2 -> 97.855825 | AG13: =AD13/(2*AE13) -> 0.22776459 | AH13: =(AE13/100)*Reference!$L$21*(H13/1000)/(Reference!$W$21) -> 29.282848 | AI13: =(AE13/100)*Reference!$L$21*(H13/1000)/(Reference!$P$26) -> 76.080888 | AJ13: =(AE13/100)*Reference!$L$21*(H13/1000)/(Reference!$P$21) -> 175.92517 | AK13: =AH13/Reference!$R$21 -> 485.45433 | AL13: =AI13/(Reference!$R$21) -> 1261.2775 | AM13: =AB13/(Reference!$R$21) -> 29.801124 | AN13: =S13/H13 -> 28.44806 | AO13: =0.00002*(AO$2/293)^1.67 -> 0.00030579718 | AQ13: =AE13/AD13 -> 2.195249 | AR13: =(1/0.0557)*(H13/1000)^2*V13*(AE13/100)/6*((AE13/100)-(AD13/100)*0.75) -> 0.0022060575 | AS13: =0.75*AR13/(2*(AE13/100)-(AD13/100)) -> 0.0021894836 | AT13: =1000*(S13/1000)/(AD13/100)-(0.75*AR13/(AD13/100)^2)*LN(ABS(1+((AD13/100)*(S13/1000)/(0.75*AR13))*(1-((AD13/100)/(2*(AE13/100)))))) -> 204.18805 | AU13: =1/(AD13/100)*LN((4*AD13/100*(S13/1000+AS13)+3*AR13)/(4*AD13/100*AS13+3*AR13)) -> 7.8368556 | AV13: =1/(AD13/100)*LN((4*AD13/100*(S13/2000+AS13)+3*AR13)/(4*AD13/100*AS13+3*AR13)) -> 5.4479941 | AW13: =AU13-AV13 -> 2.3888615 | AX13: =1000*(S13/2000)/(AD13/100)-(0.75*AR13/(AD13/100)^2)*LN(ABS(1+((AD13/100)*(S13/2000)/(0.75*AR13))*(1-((AD13/100)/(2*(AE13/100)))))) -> 102.08267 | AY13: =AT13-AX13 -> 102.10538 | AZ13: =AX13/AY13 -> 0.99977759 | BD13: 45.522586 | BE13: 0.22776459 | BF13: 0.22776459 | BG13: =BF13*2 -> 0.45552918 | BH13: 45.522586 | BI13: 29.801124 | BK13: u_a/2u_f | BL13: u_a/u_f | BM13: SP | BN13: mf/Zst
A14: 52 | B14: 0.4853125 | C14: 0.48664352 | D14: 0.48574074 | E14: 25 | F14: P7-1 | G14: Propane | H14: 0.762 | I14: 101325 | J14: 44.1 | K14: 44.1 | L14: 1 | M14: 350 | N14: 42 | O14: 85 | P14: 4.1 | Q14: 250 | R14: 62 | S14: =R14*Reference!$F$42+Reference!$F$43 -> 105.45049 | T14: 34 | U14: =T14*-Reference!$F$42 -> 7.8110965 | V14: =Reference!$L$21 -> 1826.8482 | W14: 2264.12 | X14: =Reference!$W$21 -> 0.048845 | Y14: =(20*10^-6)*(600/298)^(1.67) -> 6.4357835e-05 | Z14: =M14*Reference!$L$6 -> 126 | AA14: =Z14 -> 126 | AB14: =Z14*Reference!$L$21/(60*10^3) -> 3.8363813 | AC14: =AB14 -> 3.8363813 | AD14: =N14*Reference!$F$10+Reference!$F$11 -> 33.570677 | AE14: =(Z14/(PI()/4*((H14/10)^2)*60)) -> 460.48922 | AF14: =AE14*2 -> 920.97845 | AG14: =AD14/(2*AE14) -> 0.036451099 | AH14: =(AE14/100)*Reference!$L$21*(H14/1000)/(Reference!$W$21) -> 131.23715 | AI14: =(AE14/100)*Reference!$L$21*(H14/1000)/(Reference!$P$26) -> 340.97227 | AJ14: =(AE14/100)*Reference!$L$21*(H14/1000)/(Reference!$P$21) -> 788.44513 | AK14: =AH14/Reference!$R$21 -> 2175.6642 | AL14: =AI14/(Reference!$R$21) -> 5652.6765 | AM14: =AB14/(Reference!$R$21) -> 63.599959 | AN14: =S14/H14 -> 138.38648 | AO14: =0.00002*(AO$2/293)^1.67 -> 0.00030579718 | AQ14: =AE14/AD14 -> 13.717008 | AR14: =(1/0.0557)*(H14/1000)^2*V14*(AE14/100)/6*((AE14/100)-(AD14/100)*0.75) -> 0.063624634 | AS14: =0.75*AR14/(2*(AE14/100)-(AD14/100)) -> 0.0053772885 | AT14: =1000*(S14/1000)/(AD14/100)-(0.75*AR14/(AD14/100)^2)*LN(ABS(1+((AD14/100)*(S14/1000)/(0.75*AR14))*(1-((AD14/100)/(2*(AE14/100)))))) -> 313.88654 | AU14: =1/(AD14/100)*LN((4*AD14/100*(S14/1000+AS14)+3*AR14)/(4*AD14/100*AS14+3*AR14)) -> 1.6064835 | AV14: =1/(AD14/100)*LN((4*AD14/100*(S14/2000+AS14)+3*AR14)/(4*AD14/100*AS14+3*AR14)) -> 0.91025272 | AW14: =AU14-AV14 -> 0.69623074 | AX14: =1000*(S14/2000)/(AD14/100)-(0.75*AR14/(AD14/100)^2)*LN(ABS(1+((AD14/100)*(S14/2000)/(0.75*AR14))*(1-((AD14/100)/(2*(AE14/100)))))) -> 156.92806 | AY14: =AT14-AX14 -> 156.95848 | AZ14: =AX14/AY14 -> 0.99980618 | BD14: 105.45049 | BE14: 0.036451099 | BK14: 0.036451099 | BL14: =BK14*2 -> 0.072902198 | BM14: 105.45049 | BN14: 63.599959
A15: 52 | B15: 0.4880787 | C15: 0.48913194 | D15: 0.48825231 | E15: 27 | F15: P7-2 | G15: Propane | H15: 0.762 | I15: 101325 | J15: 44.1 | K15: 44.1 | L15: 1 | M15: 240 | N15: 29 | O15: 66 | P15: 4.1 | Q15: 250 | R15: 192 | S15: =R15*Reference!$F$42+Reference!$F$43 -> 75.584537 | T15: 30 | U15: =T15*-Reference!$F$42 -> 6.892144 | V15: =Reference!$L$21 -> 1826.8482 | W15: 2264.12 | X15: =Reference!$W$21 -> 0.048845 | Y15: =(20*10^-6)*(600/298)^(1.67) -> 6.4357835e-05 | Z15: =M15*Reference!$L$6 -> 86.4 | AA15: =Z15 -> 86.4 | AB15: =Z15*Reference!$L$21/(60*10^3) -> 2.6306615 | AC15: =AB15 -> 2.6306615 | AD15: =N15*Reference!$F$10+Reference!$F$11 -> 21.347877 | AE15: =(Z15/(PI()/4*((H15/10)^2)*60)) -> 315.76404 | AF15: =AE15*2 -> 631.52808 | AG15: =AD15/(2*AE15) -> 0.033803527 | AH15: =(AE15/100)*Reference!$L$21*(H15/1000)/(Reference!$W$21) -> 89.991191 | AI15: =(AE15/100)*Reference!$L$21*(H15/1000)/(Reference!$P$26) -> 233.80956 | AJ15: =(AE15/100)*Reference!$L$21*(H15/1000)/(Reference!$P$21) -> 540.64809 | AK15: =AH15/Reference!$R$21 -> 1491.884 | AL15: =AI15/(Reference!$R$21) -> 3876.121 | AM15: =AB15/(Reference!$R$21) -> 43.6114 | AN15: =S15/H15 -> 99.192305 | AO15: =0.00002*(AO$2/293)^1.67 -> 0.00030579718 | AQ15: =AE15/AD15 -> 14.791356 | AR15: =(1/0.0557)*(H15/1000)^2*V15*(AE15/100)/6*((AE15/100)-(AD15/100)*0.75) -> 0.030042244 | AS15: =0.75*AR15/(2*(AE15/100)-(AD15/100)) -> 0.0036926277 | AT15: =1000*(S15/1000)/(AD15/100)-(0.75*AR15/(AD15/100)^2)*LN(ABS(1+((AD15/100)*(S15/1000)/(0.75*AR15))*(1-((AD15/100)/(2*(AE15/100)))))) -> 353.80116 | AU15: =1/(AD15/100)*LN((4*AD15/100*(S15/1000+AS15)+3*AR15)/(4*AD15/100*AS15+3*AR15)) -> 2.4633239 | AV15: =1/(AD15/100)*LN((4*AD15/100*(S15/2000+AS15)+3*AR15)/(4*AD15/100*AS15+3*AR15)) -> 1.3917526 | AW15: =AU15-AV15 -> 1.0715713 | AX15: =1000*(S15/2000)/(AD15/100)-(0.75*AR15/(AD15/100)^2)*LN(ABS(1+((AD15/100)*(S15/2000)/(0.75*AR15))*(1-((AD15/100)/(2*(AE15/100)))))) -> 176.88368 | AY15: =AT15-AX15 -> 176.91747 | AZ15: =AX15/AY15 -> 0.99980899 | BD15: 75.584537 | BE15: 0.033803527 | BK15: 0.033803527 | BL15: =BK15*2 -> 0.067607054 | BM15: 75.584537 | BN15: 43.6114
A16: 52 | B16: 0.4927662 | C16: 0.49356481 | D16: 0.4928588 | E16: 29 | F16: P7-3 | G16: Propane | H16: 0.762 | I16: 101325 | J16: 44.1 | K16: 44.1 | L16: 1 | M16: 206 | N16: 24 | O16: 57 | P16: 4.1 | Q16: 50 | R16: 241 | S16: =R16*Reference!$F$42+Reference!$F$43 -> 64.327368 | T16: 29 | U16: =T16*-Reference!$F$42 -> 6.6624059 | V16: =Reference!$L$21 -> 1826.8482 | W16: 2264.12 | X16: =Reference!$W$21 -> 0.048845 | Y16: =(20*10^-6)*(600/298)^(1.67) -> 6.4357835e-05 | Z16: =M16*Reference!$L$6 -> 74.16 | AA16: =Z16 -> 74.16 | AB16: =Z16*Reference!$L$21/(60*10^3) -> 2.2579844 | AC16: =AB16 -> 2.2579844 | AD16: =N16*Reference!$F$10+Reference!$F$11 -> 16.6468 | AE16: =(Z16/(PI()/4*((H16/10)^2)*60)) -> 271.0308 | AF16: =AE16*2 -> 542.0616 | AG16: =AD16/(2*AE16) -> 0.030710162 | AH16: =(AE16/100)*Reference!$L$21*(H16/1000)/(Reference!$W$21) -> 77.242439 | AI16: =(AE16/100)*Reference!$L$21*(H16/1000)/(Reference!$P$26) -> 200.68654 | AJ16: =(AE16/100)*Reference!$L$21*(H16/1000)/(Reference!$P$21) -> 464.05628 | AK16: =AH16/Reference!$R$21 -> 1280.5338 | AL16: =AI16/(Reference!$R$21) -> 3327.0039 | AM16: =AB16/(Reference!$R$21) -> 37.433119 | AN16: =S16/H16 -> 84.419118 | AO16: =0.00002*(AO$2/293)^1.67 -> 0.00030579718 | AQ16: =AE16/AD16 -> 16.281256 | AR16: =(1/0.0557)*(H16/1000)^2*V16*(AE16/100)/6*((AE16/100)-(AD16/100)*0.75) -> 0.022241391 | AS16: =0.75*AR16/(2*(AE16/100)-(AD16/100)) -> 0.0031748331 | AT16: =1000*(S16/1000)/(AD16/100)-(0.75*AR16/(AD16/100)^2)*LN(ABS(1+((AD16/100)*(S16/1000)/(0.75*AR16))*(1-((AD16/100)/(2*(AE16/100)))))) -> 386.13361 | AU16: =1/(AD16/100)*LN((4*AD16/100*(S16/1000+AS16)+3*AR16)/(4*AD16/100*AS16+3*AR16)) -> 2.9063069 | AV16: =1/(AD16/100)*LN((4*AD16/100*(S16/2000+AS16)+3*AR16)/(4*AD16/100*AS16+3*AR16)) -> 1.627227 | AW16: =AU16-AV16 -> 1.2790799 | AX16: =1000*(S16/2000)/(AD16/100)-(0.75*AR16/(AD16/100)^2)*LN(ABS(1+((AD16/100)*(S16/2000)/(0.75*AR16))*(1-((AD16/100)/(2*(AE16/100)))))) -> 193.04936 | AY16: =AT16-AX16 -> 193.08425 | AZ16: =AX16/AY16 -> 0.99981932 | BD16: 64.327368 | BE16: 0.030710162 | BK16: 0.030710162 | BL16: =BK16*2 -> 0.061420324 | BM16: 64.327368 | BN16: 37.433119
A17: 52 | B17: 0.67644676 | C17: 0.67743056 | D17: 0.67650463 | F17: 75P16-1 | G17: 75 % Propylene | H17: 1.6002 | I17: 101325 | J17: =0.75*42.08+0.25*28.0134 -> 38.56335 | K17: 42.08 | L17: 0.75 | M17: 149 | N17: 75 | O17: 139 | P17: 3.05 | Q17: 250 | R17: 357 | S17: =R17*Reference!$F$42+Reference!$F$43 -> 37.677745 | T17: 23 | U17: =T17*-Reference!$F$42 -> 5.2839771 | V17: =Reference!$L$22 -> 1743.4481 | W17: 2317.4 | X17: =Reference!$W$23 -> 0.049485 | Y17: =(20*10^-6)*(600/298)^(1.67) -> 6.4357835e-05 | Z17: =M17*Reference!$L$8 -> 71.659824 | AA17: =Z17*0.75 -> 53.744868 | AB17: =Z17*Reference!$L$23/(60*10^3) -> 1.908064 | AC17: =AA17*Reference!$L$22/(60*1000) -> 1.5616898 | AD17: =N17*Reference!$F$10+Reference!$F$11 -> 64.597784 | AE17: =(Z17/(PI()/4*((H17/10)^2)*60)) -> 59.386273 | AF17: =AE17*2 -> 118.77255 | AG17: =AD17/(2*AE17) -> 0.54387808 | AH17: =(AE17/100)*Reference!$L$23*(H17/1000)/(Reference!$W$20) -> 30.31185 | AI17: =(AE17/100)*Reference!$L$23*(H17/1000)/(Reference!$P$26) -> 80.755282 | AJ17: =(AE17/100)*Reference!$L$23*(H17/1000)/(Reference!$P$23) -> 144.10545 | AK17: =AH17/Reference!$R$23 -> 394.77503 | AL17: =AI17/(Reference!$R$23) -> 1051.7395 | AM17: =AB17/(Reference!$R$23) -> 24.850217 | AN17: =S17/H17 -> 23.545647 | AO17: =0.00002*(AO$2/293)^1.67 -> 0.00030579718 | AQ17: =AE17/AD17 -> 0.91932369 | AR17: =(1/0.0557)*(H17/1000)^2*V17*(AE17/100)/6*((AE17/100)-(AD17/100)*0.75) -> 0.00086770587 | AS17: =0.75*AR17/(2*(AE17/100)-(AD17/100)) -> 0.0012012594 | AT17: =1000*(S17/1000)/(AD17/100)-(0.75*AR17/(AD17/100)^2)*LN(ABS(1+((AD17/100)*(S17/1000)/(0.75*AR17))*(1-((AD17/100)/(2*(AE17/100)))))) -> 58.32217 | AU17: =1/(AD17/100)*LN((4*AD17/100*(S17/1000+AS17)+3*AR17)/(4*AD17/100*AS17+3*AR17)) -> 4.4794659 | AV17: =1/(AD17/100)*LN((4*AD17/100*(S17/2000+AS17)+3*AR17)/(4*AD17/100*AS17+3*AR17)) -> 3.4898785 | AW17: =AU17-AV17 -> 0.98958732 | AX17: =1000*(S17/2000)/(AD17/100)-(0.75*AR17/(AD17/100)^2)*LN(ABS(1+((AD17/100)*(S17/2000)/(0.75*AR17))*(1-((AD17/100)/(2*(AE17/100)))))) -> 29.159826 | AY17: =AT17-AX17 -> 29.162344 | AZ17: =AX17/AY17 -> 0.99991363 | BD17: 37.677745 | BE17: 0.54387808 | BF17: 0.54387808 | BG17: =BF17*2 -> 1.0877562 | BH17: 37.677745 | BI17: 24.850217 | BK17: 0.071272374 | BL17: =BK17*2 -> 0.14254475 | BM17: 39.51565 | BN17: 24.850217
A18: 173 | B18: 0.4428588 | C18: 0.44347222 | D18: 0.44332176 | F18: 75P16-2 | G18: 75 % Propylene | H18: 1.6002 | I18: 101325 | J18: =0.75*42.08+0.25*28.0134 -> 38.56335 | K18: 42.08 | L18: 0.75 | M18: 147 | N18: 69 | O18: 139 | P18: 3.24 | Q18: 250 | R18: 365 | S18: =R18*Reference!$B$23+Reference!$B$24 -> 35.83984 | T18: 24 | U18: =T18*-Reference!$B$23 -> 5.5137152 | V18: =Reference!$L$22 -> 1743.4481 | W18: 2317.4 | X18: =Reference!$W$23 -> 0.049485 | Y18: =(20*10^-6)*(600/298)^(1.67) -> 6.4357835e-05 | Z18: =M18*Reference!$L$8 -> 70.697947 | AA18: =Z18*0.75 -> 53.02346 | AB18: =Z18*Reference!$L$23/(60*10^3) -> 1.8824524 | AC18: =AA18*Reference!$L$22/(60*1000) -> 1.5407275 | AD18: =N18*Reference!$F$10+Reference!$F$11 -> 58.956492 | AE18: =(Z18/(PI()/4*((H18/10)^2)*60)) -> 58.589142 | AF18: =AE18*2 -> 117.17828 | AG18: =AD18/(2*AE18) -> 0.50313496 | AH18: =(AE18/100)*Reference!$L$23*(H18/1000)/(Reference!$W$20) -> 29.904979 | AI18: =(AE18/100)*Reference!$L$23*(H18/1000)/(Reference!$P$26) -> 79.671318 | AJ18: =(AE18/100)*Reference!$L$23*(H18/1000)/(Reference!$P$23) -> 142.17114 | AK18: =AH18/Reference!$R$23 -> 389.47604 | AL18: =AI18/(Reference!$R$23) -> 1037.6222 | AM18: =AB18/(Reference!$R$23) -> 24.516657 | AN18: =S18/H18 -> 22.3971 | AO18: =0.00002*(AO$2/293)^1.67 -> 0.00030579718 | AQ18: =AE18/AD18 -> 0.99376914 | AR18: =(1/0.0557)*(H18/1000)^2*V18*(AE18/100)/6*((AE18/100)-(AD18/100)*0.75) -> 0.0011248086 | AS18: =0.75*AR18/(2*(AE18/100)-(AD18/100)) -> 0.001448953 | AT18: =1000*(S18/1000)/(AD18/100)-(0.75*AR18/(AD18/100)^2)*LN(ABS(1+((AD18/100)*(S18/1000)/(0.75*AR18))*(1-((AD18/100)/(2*(AE18/100)))))) -> 60.784012 | AU18: =1/(AD18/100)*LN((4*AD18/100*(S18/1000+AS18)+3*AR18)/(4*AD18/100*AS18+3*AR18)) -> 4.4076744 | AV18: =1/(AD18/100)*LN((4*AD18/100*(S18/2000+AS18)+3*AR18)/(4*AD18/100*AS18+3*AR18)) -> 3.353666 | AW18: =AU18-AV18 -> 1.0540083 | AX18: =1000*(S18/2000)/(AD18/100)-(0.75*AR18/(AD18/100)^2)*LN(ABS(1+((AD18/100)*(S18/2000)/(0.75*AR18))*(1-((AD18/100)/(2*(AE18/100)))))) -> 30.390361 | AY18: =AT18-AX18 -> 30.393651 | AZ18: =AX18/AY18 -> 0.99989173 | BD18: 35.83984 | BE18: 0.50313496 | BF18: 0.50313496 | BG18: =BF18*2 -> 1.0062699 | BH18: 35.83984 | BI18: 24.516657 | BK18: 0.060007742 | BL18: =BK18*2 -> 0.12001548 | BM18: 21.973157 | BN18: 11.674598
A19: 52 | B19: Ku LOS | C19: 0.68560185 | D19: 0.68527778 | F19: 75P16-3 | G19: 75 % Propylene | H19: 1.6002 | I19: 101325 | J19: =0.75*42.08+0.25*28.0134 -> 38.56335 | K19: 42.08 | L19: 0.75 | M19: 117 | N19: 61 | O19: 119 | P19: 2.9 | Q19: 250 | R19: 383 | S19: =R19*Reference!$F$42+Reference!$F$43 -> 31.704553 | T19: 26 | U19: =T19*-Reference!$F$42 -> 5.9731915 | V19: =Reference!$L$22 -> 1743.4481 | W19: 2317.4 | X19: =Reference!$W$23 -> 0.049485 | Y19: =(20*10^-6)*(600/298)^(1.67) -> 6.4357835e-05 | Z19: =M19*Reference!$L$8 -> 56.269795 | AA19: =Z19*0.75 -> 42.202346 | AB19: =Z19*Reference!$L$23/(60*10^3) -> 1.4982784 | AC19: =AA19*Reference!$L$22/(60*1000) -> 1.2262933 | AD19: =N19*Reference!$F$10+Reference!$F$11 -> 51.434769 | AE19: =(Z19/(PI()/4*((H19/10)^2)*60)) -> 46.632174 | AF19: =AE19*2 -> 93.264349 | AG19: =AD19/(2*AE19) -> 0.55149443 | AH19: =(AE19/100)*Reference!$L$23*(H19/1000)/(Reference!$W$20) -> 23.801922 | AI19: =(AE19/100)*Reference!$L$23*(H19/1000)/(Reference!$P$26) -> 63.411866 | AJ19: =(AE19/100)*Reference!$L$23*(H19/1000)/(Reference!$P$23) -> 113.15662 | AK19: =AH19/Reference!$R$23 -> 309.99113 | AL19: =AI19/(Reference!$R$23) -> 825.86255 | AM19: =AB19/(Reference!$R$23) -> 19.513257 | AN19: =S19/H19 -> 19.812869 | AO19: =0.00002*(AO$2/293)^1.67 -> 0.00030579718 | AQ19: =AE19/AD19 -> 0.90662747 | AR19: =(1/0.0557)*(H19/1000)^2*V19*(AE19/100)/6*((AE19/100)-(AD19/100)*0.75) -> 0.00050183565 | AS19: =0.75*AR19/(2*(AE19/100)-(AD19/100)) -> 0.00089978608 | AT19: =1000*(S19/1000)/(AD19/100)-(0.75*AR19/(AD19/100)^2)*LN(ABS(1+((AD19/100)*(S19/1000)/(0.75*AR19))*(1-((AD19/100)/(2*(AE19/100)))))) -> 61.636022 | AU19: =1/(AD19/100)*LN((4*AD19/100*(S19/1000+AS19)+3*AR19)/(4*AD19/100*AS19+3*AR19)) -> 5.8659065 | AV19: =1/(AD19/100)*LN((4*AD19/100*(S19/2000+AS19)+3*AR19)/(4*AD19/100*AS19+3*AR19)) -> 4.6111814 | AW19: =AU19-AV19 -> 1.2547251 | AX19: =1000*(S19/2000)/(AD19/100)-(0.75*AR19/(AD19/100)^2)*LN(ABS(1+((AD19/100)*(S19/2000)/(0.75*AR19))*(1-((AD19/100)/(2*(AE19/100)))))) -> 30.816783 | AY19: =AT19-AX19 -> 30.819239 | AZ19: =AX19/AY19 -> 0.99992031 | BD19: 31.704553 | BE19: 0.55149443 | BF19: 0.55149443 | BG19: =BF19*2 -> 1.1029889 | BH19: 31.704553 | BI19: 19.513257 | BK19: 0.061772675 | BL19: =BK19*2 -> 0.12354535 | BM19: 20.154749 | BN19: 11.341038
A20: 173 | B20: 0.46402778 | C20: 0.46506944 | D20: 0.46489583 | F20: 75P16-4 | G20: 75 % Propylene | H20: 1.6002 | I20: 101325 | J20: =0.75*42.08+0.25*28.0134 -> 38.56335 | K20: 42.08 | L20: 0.75 | M20: 105 | N20: 51 | O20: 98 | P20: 2.29 | Q20: 250 | R20: 405 | S20: =R20*Reference!$B$23+Reference!$B$24 -> 26.650314 | T20: 23 | U20: =T20*-Reference!$B$23 -> 5.2839771 | V20: =Reference!$L$22 -> 1743.4481 | W20: 2317.4 | X20: =Reference!$W$23 -> 0.049485 | Y20: =(20*10^-6)*(600/298)^(1.67) -> 6.4357835e-05 | Z20: =M20*Reference!$L$8 -> 50.498534 | AA20: =Z20*0.75 -> 37.8739 | AB20: =Z20*Reference!$L$23/(60*10^3) -> 1.3446089 | AC20: =AA20*Reference!$L$22/(60*1000) -> 1.1005197 | AD20: =N20*Reference!$F$10+Reference!$F$11 -> 42.032615 | AE20: =(Z20/(PI()/4*((H20/10)^2)*60)) -> 41.849387 | AF20: =AE20*2 -> 83.698775 | AG20: =AD20/(2*AE20) -> 0.50218913 | AH20: =(AE20/100)*Reference!$L$23*(H20/1000)/(Reference!$W$20) -> 21.360699 | AI20: =(AE20/100)*Reference!$L$23*(H20/1000)/(Reference!$P$26) -> 56.908085 | AJ20: =(AE20/100)*Reference!$L$23*(H20/1000)/(Reference!$P$23) -> 101.55082 | AK20: =AH20/Reference!$R$23 -> 278.19717 | AL20: =AI20/(Reference!$R$23) -> 741.1587 | AM20: =AB20/(Reference!$R$23) -> 17.511898 | AN20: =S20/H20 -> 16.654365 | AO20: =0.00002*(AO$2/293)^1.67 -> 0.00030579718 | AQ20: =AE20/AD20 -> 0.99564082 | AR20: =(1/0.0557)*(H20/1000)^2*V20*(AE20/100)/6*((AE20/100)-(AD20/100)*0.75) -> 0.00057720112 | AS20: =0.75*AR20/(2*(AE20/100)-(AD20/100)) -> 0.0010389747 | AT20: =1000*(S20/1000)/(AD20/100)-(0.75*AR20/(AD20/100)^2)*LN(ABS(1+((AD20/100)*(S20/1000)/(0.75*AR20))*(1-((AD20/100)/(2*(AE20/100)))))) -> 63.397448 | AU20: =1/(AD20/100)*LN((4*AD20/100*(S20/1000+AS20)+3*AR20)/(4*AD20/100*AS20+3*AR20)) -> 6.2583622 | AV20: =1/(AD20/100)*LN((4*AD20/100*(S20/2000+AS20)+3*AR20)/(4*AD20/100*AS20+3*AR20)) -> 4.7747878 | AW20: =AU20-AV20 -> 1.4835744 | AX20: =1000*(S20/2000)/(AD20/100)-(0.75*AR20/(AD20/100)^2)*LN(ABS(1+((AD20/100)*(S20/2000)/(0.75*AR20))*(1-((AD20/100)/(2*(AE20/100)))))) -> 31.697029 | AY20: =AT20-AX20 -> 31.700419 | AZ20: =AX20/AY20 -> 0.99989307 | BD20: 26.650314 | BE20: 0.50218913 | BF20: 0.50218913 | BG20: =BF20*2 -> 1.0043783 | BH20: 26.650314 | BI20: 17.511898 | BK20: 0.069788742 | BL20: =BK20*2 -> 0.13957748 | BM20: 43.976158 | BN20: 26.017676
A21: 52 | B21: 0.6821412 | C21: 0.68333333 | D21: 0.68287037 | F21: 75P16-5 | G21: 75 % Propylene | H21: 1.6002 | I21: 101325 | J21: =0.75*42.08+0.25*28.0134 -> 38.56335 | K21: 42.08 | L21: 0.75 | M21: 79 | N21: 37 | O21: 81 | P21: 1.66 | Q21: 250 | R21: 429 | S21: =R21*Reference!$F$42+Reference!$F$43 -> 21.136599 | T21: 29 | U21: =T21*-Reference!$F$42 -> 6.6624059 | V21: =Reference!$L$22 -> 1743.4481 | W21: 2317.4 | X21: =Reference!$W$23 -> 0.049485 | Y21: =(20*10^-6)*(600/298)^(1.67) -> 6.4357835e-05 | Z21: =M21*Reference!$L$8 -> 37.994135 | AA21: =Z21*0.75 -> 28.495601 | AB21: =Z21*Reference!$L$23/(60*10^3) -> 1.0116581 | AC21: =AA21*Reference!$L$22/(60*1000) -> 0.82801004 | AD21: =N21*Reference!$F$10+Reference!$F$11 -> 28.8696 | AE21: =(Z21/(PI()/4*((H21/10)^2)*60)) -> 31.486682 | AF21: =AE21*2 -> 62.973364 | AG21: =AD21/(2*AE21) -> 0.45844144 | AH21: =(AE21/100)*Reference!$L$23*(H21/1000)/(Reference!$W$20) -> 16.071383 | AI21: =(AE21/100)*Reference!$L$23*(H21/1000)/(Reference!$P$26) -> 42.816559 | AJ21: =(AE21/100)*Reference!$L$23*(H21/1000)/(Reference!$P$23) -> 76.4049 | AK21: =AH21/Reference!$R$23 -> 209.31025 | AL21: =AI21/(Reference!$R$23) -> 557.63369 | AM21: =AB21/(Reference!$R$23) -> 13.175618 | AN21: =S21/H21 -> 13.208723 | AO21: =0.00002*(AO$2/293)^1.67 -> 0.00030579718 | AQ21: =AE21/AD21 -> 1.0906518 | AR21: =(1/0.0557)*(H21/1000)^2*V21*(AE21/100)/6*((AE21/100)-(AD21/100)*0.75) -> 0.00041364665 | AS21: =0.75*AR21/(2*(AE21/100)-(AD21/100)) -> 0.0009096796 | AT21: =1000*(S21/1000)/(AD21/100)-(0.75*AR21/(AD21/100)^2)*LN(ABS(1+((AD21/100)*(S21/1000)/(0.75*AR21))*(1-((AD21/100)/(2*(AE21/100)))))) -> 73.204896 | AU21: =1/(AD21/100)*LN((4*AD21/100*(S21/1000+AS21)+3*AR21)/(4*AD21/100*AS21+3*AR21)) -> 8.5054055 | AV21: =1/(AD21/100)*LN((4*AD21/100*(S21/2000+AS21)+3*AR21)/(4*AD21/100*AS21+3*AR21)) -> 6.3896518 | AW21: =AU21-AV21 -> 2.1157537 | AX21: =1000*(S21/2000)/(AD21/100)-(0.75*AR21/(AD21/100)^2)*LN(ABS(1+((AD21/100)*(S21/2000)/(0.75*AR21))*(1-((AD21/100)/(2*(AE21/100)))))) -> 36.600152 | AY21: =AT21-AX21 -> 36.604745 | AZ21: =AX21/AY21 -> 0.99987453 | BD21: 21.136599 | BE21: 0.45844144 | BF21: 0.45844144 | BG21: =BF21*2 -> 0.91688288 | BH21: 21.136599 | BI21: 13.175618 | BK21: 0.058961771 | BL21: =BK21*2 -> 0.11792354 | BM21: 14.213981 | BN21: 7.6642196
A22: 52 | B22: no ku | C22: 0.6741088 | D22: 0.67359954 | F22: 75P16-6 | G22: 75 % Propylene | H22: 1.6002 | I22: 101325 | J22: =0.75*42.08+0.25*28.0134 -> 38.56335 | K22: 42.08 | L22: 0.75 | M22: 50 | N22: 20 | O22: 55 | P22: 1.12 | Q22: 250 | R22: 458 | S22: =R22*Reference!$F$42+Reference!$F$43 -> 14.474193 | T22: 27 | U22: =T22*-Reference!$F$42 -> 6.2029296 | V22: =Reference!$L$22 -> 1743.4481 | W22: 2317.4 | X22: =Reference!$W$23 -> 0.049485 | Y22: =(20*10^-6)*(600/298)^(1.67) -> 6.4357835e-05 | Z22: =M22*Reference!$L$8 -> 24.046921 | AA22: =Z22*0.75 -> 18.035191 | AB22: =Z22*Reference!$L$23/(60*10^3) -> 0.64028993 | AC22: =AA22*Reference!$L$22/(60*1000) -> 0.52405698 | AD22: =N22*Reference!$F$10+Reference!$F$11 -> 12.885938 | AE22: =(Z22/(PI()/4*((H22/10)^2)*60)) -> 19.92828 | AF22: =AE22*2 -> 39.856559 | AG22: =AD22/(2*AE22) -> 0.32330784 | AH22: =(AE22/100)*Reference!$L$23*(H22/1000)/(Reference!$W$20) -> 10.171762 | AI22: =(AE22/100)*Reference!$L$23*(H22/1000)/(Reference!$P$26) -> 27.099088 | AJ22: =(AE22/100)*Reference!$L$23*(H22/1000)/(Reference!$P$23) -> 48.357532 | AK22: =AH22/Reference!$R$23 -> 132.47484 | AL22: =AI22/(Reference!$R$23) -> 352.93271 | AM22: =AB22/(Reference!$R$23) -> 8.3389988 | AN22: =S22/H22 -> 9.0452402 | AO22: =0.00002*(AO$2/293)^1.67 -> 0.00030579718 | AQ22: =AE22/AD22 -> 1.5465137 | AR22: =(1/0.0557)*(H22/1000)^2*V22*(AE22/100)/6*((AE22/100)-(AD22/100)*0.75) -> 0.00027323115 | AS22: =0.75*AR22/(2*(AE22/100)-(AD22/100)) -> 0.00075980216 | AT22: =1000*(S22/1000)/(AD22/100)-(0.75*AR22/(AD22/100)^2)*LN(ABS(1+((AD22/100)*(S22/1000)/(0.75*AR22))*(1-((AD22/100)/(2*(AE22/100)))))) -> 112.3012 | AU22: =1/(AD22/100)*LN((4*AD22/100*(S22/1000+AS22)+3*AR22)/(4*AD22/100*AS22+3*AR22)) -> 15.275334 | AV22: =1/(AD22/100)*LN((4*AD22/100*(S22/2000+AS22)+3*AR22)/(4*AD22/100*AS22+3*AR22)) -> 10.910919 | AW22: =AU22-AV22 -> 4.3644152 | AX22: =1000*(S22/2000)/(AD22/100)-(0.75*AR22/(AD22/100)^2)*LN(ABS(1+((AD22/100)*(S22/2000)/(0.75*AR22))*(1-((AD22/100)/(2*(AE22/100)))))) -> 56.145394 | AY22: =AT22-AX22 -> 56.155805 | AZ22: =AX22/AY22 -> 0.99981461 | BD22: 14.474193 | BE22: 0.32330784 | BF22: 0.32330784 | BG22: =BF22*2 -> 0.64661568 | BH22: 14.474193 | BI22: 8.3389988
A23: 119 | B23: 0.43630787 | C23: 0.43809028 | D23: 0.43715278 | F23: 75P16-7 | G23: 75 % Propylene | H23: 1.6002 | I23: 101325 | J23: =0.75*42.08+0.25*28.0134 -> 38.56335 | K23: 42.08 | L23: 0.75 | M23: 49 | N23: 20 | O23: 79 | P23: 1.18 | Q23: ? | R23: 458 | S23: =R23*Reference!$K$78+Reference!$K$79 -> 14.158541 | T23: 32 | U23: =T23*-Reference!$K$78 -> 7.3546803 | V23: =Reference!$L$22 -> 1743.4481 | W23: 2317.4 | X23: =Reference!$W$23 -> 0.049485 | Y23: =(20*10^-6)*(600/298)^(1.67) -> 6.4357835e-05 | Z23: =M23*Reference!$L$8 -> 23.565982 | AA23: =0.75*Z23 -> 17.674487 | AB23: =Z23*Reference!$L$23/(60*10^3) -> 0.62748413 | AC23: =AA23*Reference!$L$22/(60*1000) -> 0.51357584 | AD23: =N23*Reference!$F$10+Reference!$F$11 -> 12.885938 | AE23: =(Z23/(PI()/4*((H23/10)^2)*60)) -> 19.529714 | AF23: =AE23*2 -> 39.059428 | AG23: =AD23/(2*AE23) -> 0.32990596 | AH23: =(AE23/100)*Reference!$L$23*(H23/1000)/(Reference!$W$20) -> 9.9683264 | AI23: =(AE23/100)*Reference!$L$23*(H23/1000)/(Reference!$P$26) -> 26.557106 | AJ23: =(AE23/100)*Reference!$L$23*(H23/1000)/(Reference!$P$23) -> 47.390381 | AK23: =AH23/Reference!$R$23 -> 129.82535 | AL23: =AI23/(Reference!$R$23) -> 345.87406 | AM23: =AB23/(Reference!$R$23) -> 8.1722189 | AN23: =S23/H23 -> 8.847982 | AO23: =0.00002*(AO$2/293)^1.67 -> 0.00030579718 | AQ23: =AE23/AD23 -> 1.5155834 | AR23: =(1/0.0557)*(H23/1000)^2*V23*(AE23/100)/6*((AE23/100)-(AD23/100)*0.75) -> 0.0002573686 | AS23: =0.75*AR23/(2*(AE23/100)-(AD23/100)) -> 0.00073748838 | AT23: =1000*(S23/1000)/(AD23/100)-(0.75*AR23/(AD23/100)^2)*LN(ABS(1+((AD23/100)*(S23/1000)/(0.75*AR23))*(1-((AD23/100)/(2*(AE23/100)))))) -> 109.85274 | AU23: =1/(AD23/100)*LN((4*AD23/100*(S23/1000+AS23)+3*AR23)/(4*AD23/100*AS23+3*AR23)) -> 15.462376 | AV23: =1/(AD23/100)*LN((4*AD23/100*(S23/2000+AS23)+3*AR23)/(4*AD23/100*AS23+3*AR23)) -> 11.075277 | AW23: =AU23-AV23 -> 4.3870989 | AX23: =1000*(S23/2000)/(AD23/100)-(0.75*AR23/(AD23/100)^2)*LN(ABS(1+((AD23/100)*(S23/2000)/(0.75*AR23))*(1-((AD23/100)/(2*(AE23/100)))))) -> 54.921361 | AY23: =AT23-AX23 -> 54.93138 | AZ23: =AX23/AY23 -> 0.99981762 | BD23: 14.158541 | BE23: 0.32990596 | BF23: 0.32990596 | BG23: =BF23*2 -> 0.65981192 | BH23: 14.158541 | BI23: 8.1722189
A24: 119 | B24: 0.44344907 | C24: 0.44457176 | D24: 0.44366898 | F24: 75P16-8 | G24: 75 % Propylene | H24: 1.6002 | I24: 101325 | J24: =0.75*42.08+0.25*28.0134 -> 38.56335 | K24: 42.08 | L24: 0.75 | M24: 72 | N24: 35 | O24: 117 | P24: 1.4 | R24: 431 | S24: =R24*Reference!$K$78+Reference!$K$79 -> 20.364052 | T24: 30 | U24: =T24*-Reference!$K$78 -> 6.8950128 | V24: =Reference!$L$22 -> 1743.4481 | W24: 2317.4 | X24: =Reference!$W$23 -> 0.049485 | Y24: =(20*10^-6)*(600/298)^(1.67) -> 6.4357835e-05 | Z24: =M24*Reference!$L$8 -> 34.627566 | AA24: =0.75*Z24 -> 25.970674 | AB24: =Z24*Reference!$L$23/(60*10^3) -> 0.9220175 | AC24: =AA24*Reference!$L$22/(60*1000) -> 0.75464206 | AD24: =N24*Reference!$F$10+Reference!$F$11 -> 26.989169 | AE24: =(Z24/(PI()/4*((H24/10)^2)*60)) -> 28.696723 | AF24: =AE24*2 -> 57.393445 | AG24: =AD24/(2*AE24) -> 0.47024828 | AH24: =(AE24/100)*Reference!$L$23*(H24/1000)/(Reference!$W$20) -> 14.647337 | AI24: =(AE24/100)*Reference!$L$23*(H24/1000)/(Reference!$P$26) -> 39.022687 | AJ24: =(AE24/100)*Reference!$L$23*(H24/1000)/(Reference!$P$23) -> 69.634846 | AK24: =AH24/Reference!$R$23 -> 190.76378 | AL24: =AI24/(Reference!$R$23) -> 508.22311 | AM24: =AB24/(Reference!$R$23) -> 12.008158 | AN24: =S24/H24 -> 12.725942 | AO24: =0.00002*(AO$2/293)^1.67 -> 0.00030579718 | AQ24: =AE24/AD24 -> 1.0632681 | AR24: =(1/0.0557)*(H24/1000)^2*V24*(AE24/100)/6*((AE24/100)-(AD24/100)*0.75) -> 0.00032410753 | AS24: =0.75*AR24/(2*(AE24/100)-(AD24/100)) -> 0.00079949492 | AT24: =1000*(S24/1000)/(AD24/100)-(0.75*AR24/(AD24/100)^2)*LN(ABS(1+((AD24/100)*(S24/1000)/(0.75*AR24))*(1-((AD24/100)/(2*(AE24/100)))))) -> 75.44413 | AU24: =1/(AD24/100)*LN((4*AD24/100*(S24/1000+AS24)+3*AR24)/(4*AD24/100*AS24+3*AR24)) -> 9.4972815 | AV24: =1/(AD24/100)*LN((4*AD24/100*(S24/2000+AS24)+3*AR24)/(4*AD24/100*AS24+3*AR24)) -> 7.204077 | AW24: =AU24-AV24 -> 2.2932045 | AX24: =1000*(S24/2000)/(AD24/100)-(0.75*AR24/(AD24/100)^2)*LN(ABS(1+((AD24/100)*(S24/2000)/(0.75*AR24))*(1-((AD24/100)/(2*(AE24/100)))))) -> 37.719854 | AY24: =AT24-AX24 -> 37.724277 | AZ24: =AX24/AY24 -> 0.99988275 | BD24: 20.364052 | BE24: 0.47024828 | BF24: 0.47024828 | BG24: =BF24*2 -> 0.94049655 | BH24: 20.364052 | BI24: 12.008158
A25: 136 | B25: 0.66488426 | C25: 0.66622685 | D25: 0.66518519 | F25: 75P16-9 | G25: 75 % Propylene | H25: 1.6002 | I25: 101325 | J25: =0.75*42.08+0.25*28.0134 -> 38.56335 | K25: 42.08 | L25: 0.75 | M25: 52 | N25: 24 | O25: 131 | P25: 1.27 | Q25: 250 | R25: 451 | S25: =R25*Reference!$F$60+Reference!$F$61 -> 15.608728 | T25: 36 | U25: =T25*-Reference!$F$60 -> 8.1828378 | V25: =Reference!$L$22 -> 1743.4481 | W25: 2317.4 | X25: =Reference!$W$23 -> 0.049485 | Y25: =(20*10^-6)*(600/298)^(1.67) -> 6.4357835e-05 | Z25: =M25*Reference!$L$8 -> 25.008798 | AA25: =0.75*Z25 -> 18.756598 | AB25: =Z25*Reference!$L$23/(60*10^3) -> 0.66590153 | AC25: =AA25*Reference!$L$22/(60*1000) -> 0.54501926 | AD25: =N25*Reference!$F$10+Reference!$F$11 -> 16.6468 | AE25: =(Z25/(PI()/4*((H25/10)^2)*60)) -> 20.725411 | AF25: =AE25*2 -> 41.450822 | AG25: =AD25/(2*AE25) -> 0.40160361 | AH25: =(AE25/100)*Reference!$L$23*(H25/1000)/(Reference!$W$20) -> 10.578632 | AI25: =(AE25/100)*Reference!$L$23*(H25/1000)/(Reference!$P$26) -> 28.183051 | AJ25: =(AE25/100)*Reference!$L$23*(H25/1000)/(Reference!$P$23) -> 50.291833 | AK25: =AH25/Reference!$R$23 -> 137.77384 | AL25: =AI25/(Reference!$R$23) -> 367.05002 | AM25: =AB25/(Reference!$R$23) -> 8.6725588 | AN25: =S25/H25 -> 9.7542356 | AO25: =0.00002*(AO$2/293)^1.67 -> 0.00030579718 | AQ25: =AE25/AD25 -> 1.2450087 | AR25: =(1/0.0557)*(H25/1000)^2*V25*(AE25/100)/6*((AE25/100)-(AD25/100)*0.75) -> 0.00022813813 | AS25: =0.75*AR25/(2*(AE25/100)-(AD25/100)) -> 0.00068982198 | AT25: =1000*(S25/1000)/(AD25/100)-(0.75*AR25/(AD25/100)^2)*LN(ABS(1+((AD25/100)*(S25/1000)/(0.75*AR25))*(1-((AD25/100)/(2*(AE25/100)))))) -> 93.749865 | AU25: =1/(AD25/100)*LN((4*AD25/100*(S25/1000+AS25)+3*AR25)/(4*AD25/100*AS25+3*AR25)) -> 13.884129 | AV25: =1/(AD25/100)*LN((4*AD25/100*(S25/2000+AS25)+3*AR25)/(4*AD25/100*AS25+3*AR25)) -> 10.288106 | AW25: =AU25-AV25 -> 3.5960234 | AX25: =1000*(S25/2000)/(AD25/100)-(0.75*AR25/(AD25/100)^2)*LN(ABS(1+((AD25/100)*(S25/2000)/(0.75*AR25))*(1-((AD25/100)/(2*(AE25/100)))))) -> 46.871493 | AY25: =AT25-AX25 -> 46.878372 | AZ25: =AX25/AY25 -> 0.99985327 | BD25: 15.608728 | BE25: 0.40160361 | BF25: 0.40160361 | BG25: =BF25*2 -> 0.80320722 | BH25: 15.608728 | BI25: 8.6725588
A26: 136 | B26: 0.66111111 | C26: 0.66283565 | D26: 0.66222222 | F26: 75P16-10 | G26: 75 % Propylene | H26: 1.6002 | I26: 101325 | J26: =0.75*42.08+0.25*28.0134 -> 38.56335 | K26: 42.08 | L26: 0.75 | M26: 61 | N26: 31 | O26: 131 | P26: 1.5 | Q26: 250 | R26: 441 | S26: =R26*Reference!$F$60+Reference!$F$61 -> 17.881738 | T26: 36 | U26: =T26*-Reference!$F$60 -> 8.1828378 | V26: =Reference!$L$22 -> 1743.4481 | W26: 2317.4 | X26: =Reference!$W$23 -> 0.049485 | Y26: =(20*10^-6)*(600/298)^(1.67) -> 6.4357835e-05 | Z26: =M26*Reference!$L$8 -> 29.337243 | AA26: =0.75*Z26 -> 22.002933 | AB26: =Z26*Reference!$L$23/(60*10^3) -> 0.78115371 | AC26: =AA26*Reference!$L$22/(60*1000) -> 0.63934952 | AD26: =N26*Reference!$F$10+Reference!$F$11 -> 23.228307 | AE26: =(Z26/(PI()/4*((H26/10)^2)*60)) -> 24.312501 | AF26: =AE26*2 -> 48.625002 | AG26: =AD26/(2*AE26) -> 0.47770295 | AH26: =(AE26/100)*Reference!$L$23*(H26/1000)/(Reference!$W$20) -> 12.409549 | AI26: =(AE26/100)*Reference!$L$23*(H26/1000)/(Reference!$P$26) -> 33.060887 | AJ26: =(AE26/100)*Reference!$L$23*(H26/1000)/(Reference!$P$23) -> 58.996189 | AK26: =AH26/Reference!$R$23 -> 161.61931 | AL26: =AI26/(Reference!$R$23) -> 430.57791 | AM26: =AB26/(Reference!$R$23) -> 10.173579 | AN26: =S26/H26 -> 11.17469 | AO26: =0.00002*(AO$2/293)^1.67 -> 0.00030579718 | AQ26: =AE26/AD26 -> 1.0466755 | AR26: =(1/0.0557)*(H26/1000)^2*V26*(AE26/100)/6*((AE26/100)-(AD26/100)*0.75) -> 0.0002238103 | AS26: =0.75*AR26/(2*(AE26/100)-(AD26/100)) -> 0.00066094318 | AT26: =1000*(S26/1000)/(AD26/100)-(0.75*AR26/(AD26/100)^2)*LN(ABS(1+((AD26/100)*(S26/1000)/(0.75*AR26))*(1-((AD26/100)/(2*(AE26/100)))))) -> 76.974335 | AU26: =1/(AD26/100)*LN((4*AD26/100*(S26/1000+AS26)+3*AR26)/(4*AD26/100*AS26+3*AR26)) -> 11.338011 | AV26: =1/(AD26/100)*LN((4*AD26/100*(S26/2000+AS26)+3*AR26)/(4*AD26/100*AS26+3*AR26)) -> 8.6525315 | AW26: =AU26-AV26 -> 2.6854795 | AX26: =1000*(S26/2000)/(AD26/100)-(0.75*AR26/(AD26/100)^2)*LN(ABS(1+((AD26/100)*(S26/2000)/(0.75*AR26))*(1-((AD26/100)/(2*(AE26/100)))))) -> 38.485012 | AY26: =AT26-AX26 -> 38.489324 | AZ26: =AX26/AY26 -> 0.99988797 | BD26: 17.881738 | BE26: 0.47770295 | BF26: 0.47770295 | BG26: =BF26*2 -> 0.95540591 | BH26: 17.881738 | BI26: 10.173579
A27: 52 | B27: 0.729375 | C27: 0.73003472 | D27: 0.72938657 | F27: 75P7-1 | G27: 75 % Propylene | H27: 0.762 | I27: 101325 | J27: =0.75*42.08+0.25*28.0134 -> 38.56335 | K27: 42.08 | L27: 0.75 | M27: 149 | N27: 46 | O27: 97 | P27: 3.4 | R27: 349 | S27: =R27*Reference!$F$42+Reference!$F$43 -> 39.51565 | T27: 21 | U27: =T27*-Reference!$F$42 -> 4.8245008 | V27: =Reference!$L$22 -> 1743.4481 | W27: 2317.4 | X27: =Reference!$W$23 -> 0.049485 | Y27: =(20*10^-6)*(600/298)^(1.67) -> 6.4357835e-05 | Z27: =M27*Reference!$L$8 -> 71.659824 | AA27: =Z27*0.75 -> 53.744868 | AB27: =Z27*Reference!$L$23/(60*10^3) -> 1.908064 | AC27: =AA27*Reference!$L$22/(60*1000) -> 1.5616898 | AD27: =N27*Reference!$F$10+Reference!$F$11 -> 37.331538 | AE27: =(Z27/(PI()/4*((H27/10)^2)*60)) -> 261.89347 | AF27: =AE27*2 -> 523.78693 | AG27: =AD27/(2*AE27) -> 0.071272374 | AH27: =(AE27/100)*Reference!$L$23*(H27/1000)/(Reference!$W$20) -> 63.654884 | AI27: =(AE27/100)*Reference!$L$23*(H27/1000)/(Reference!$P$26) -> 169.58609 | AJ27: =(AE27/100)*Reference!$L$23*(H27/1000)/(Reference!$P$23) -> 302.62143 | AK27: =AH27/Reference!$R$23 -> 829.02757 | AL27: =AI27/(Reference!$R$23) -> 2208.6529 | AM27: =AB27/(Reference!$R$23) -> 24.850217 | AN27: =S27/H27 -> 51.857808 | AO27: =0.00002*(AO$2/293)^1.67 -> 0.00030579718 | AQ27: =AE27/AD27 -> 7.0153409 | AR27: =(1/0.0557)*(H27/1000)^2*V27*(AE27/100)/6*((AE27/100)-(AD27/100)*0.75) -> 0.018554864 | AS27: =0.75*AR27/(2*(AE27/100)-(AD27/100)) -> 0.0028607244 | AT27: =1000*(S27/1000)/(AD27/100)-(0.75*AR27/(AD27/100)^2)*LN(ABS(1+((AD27/100)*(S27/1000)/(0.75*AR27))*(1-((AD27/100)/(2*(AE27/100)))))) -> 105.78214 | AU27: =1/(AD27/100)*LN((4*AD27/100*(S27/1000+AS27)+3*AR27)/(4*AD27/100*AS27+3*AR27)) -> 1.8358885 | AV27: =1/(AD27/100)*LN((4*AD27/100*(S27/2000+AS27)+3*AR27)/(4*AD27/100*AS27+3*AR27)) -> 1.0722408 | AW27: =AU27-AV27 -> 0.76364766 | AX27: =1000*(S27/2000)/(AD27/100)-(0.75*AR27/(AD27/100)^2)*LN(ABS(1+((AD27/100)*(S27/2000)/(0.75*AR27))*(1-((AD27/100)/(2*(AE27/100)))))) -> 52.88532 | AY27: =AT27-AX27 -> 52.896824 | AZ27: =AX27/AY27 -> 0.99978253 | BD27: 39.51565 | BE27: 0.071272374
A28: 136 | B28: 0.72329861 | C28: 0.72488426 | D28: 0.72465278 | F28: 75P7-2 | G28: 75 % Propylene | H28: 0.762 | I28: 101325 | J28: =0.75*42.08+0.25*28.0134 -> 38.56335 | K28: 42.08 | L28: 0.75 | M28: 70 | N28: 22 | O28: 134 | P28: 1.54 | Q28: 250 | R28: 423 | S28: =R28*Reference!$F$60+Reference!$F$61 -> 21.973157 | T28: 36 | U28: =T28*-Reference!$F$60 -> 8.1828378 | V28: =Reference!$L$22 -> 1743.4481 | W28: 2317.4 | X28: =Reference!$W$23 -> 0.049485 | Y28: =(20*10^-6)*(600/298)^(1.67) -> 6.4357835e-05 | Z28: =M28*Reference!$L$8 -> 33.665689 | AA28: =Z28*0.75 -> 25.249267 | AB28: =Z28*Reference!$L$23/(60*10^3) -> 0.8964059 | AC28: =AA28*Reference!$L$22/(60*1000) -> 0.73367978 | AD28: =N28*Reference!$F$10+Reference!$F$11 -> 14.766369 | AE28: =(Z28/(PI()/4*((H28/10)^2)*60)) -> 123.0372 | AF28: =AE28*2 -> 246.0744 | AG28: =AD28/(2*AE28) -> 0.060007742 | AH28: =(AE28/100)*Reference!$L$23*(H28/1000)/(Reference!$W$20) -> 29.904979 | AI28: =(AE28/100)*Reference!$L$23*(H28/1000)/(Reference!$P$26) -> 79.671318 | AJ28: =(AE28/100)*Reference!$L$23*(H28/1000)/(Reference!$P$23) -> 142.17114 | AK28: =AH28/Reference!$R$23 -> 389.47604 | AL28: =AI28/(Reference!$R$23) -> 1037.6222 | AM28: =AB28/(Reference!$R$23) -> 11.674598 | AN28: =S28/H28 -> 28.836164 | AO28: =0.00002*(AO$2/293)^1.67 -> 0.00030579718 | AQ28: =AE28/AD28 -> 8.3322582 | AR28: =(1/0.0557)*(H28/1000)^2*V28*(AE28/100)/6*((AE28/100)-(AD28/100)*0.75) -> 0.0041727392 | AS28: =0.75*AR28/(2*(AE28/100)-(AD28/100)) -> 0.0013529813 | AT28: =1000*(S28/1000)/(AD28/100)-(0.75*AR28/(AD28/100)^2)*LN(ABS(1+((AD28/100)*(S28/1000)/(0.75*AR28))*(1-((AD28/100)/(2*(AE28/100)))))) -> 148.70777 | AU28: =1/(AD28/100)*LN((4*AD28/100*(S28/1000+AS28)+3*AR28)/(4*AD28/100*AS28+3*AR28)) -> 4.6073945 | AV28: =1/(AD28/100)*LN((4*AD28/100*(S28/2000+AS28)+3*AR28)/(4*AD28/100*AS28+3*AR28)) -> 2.6881928 | AW28: =AU28-AV28 -> 1.9192017 | AX28: =1000*(S28/2000)/(AD28/100)-(0.75*AR28/(AD28/100)^2)*LN(ABS(1+((AD28/100)*(S28/2000)/(0.75*AR28))*(1-((AD28/100)/(2*(AE28/100)))))) -> 74.345737 | AY28: =AT28-AX28 -> 74.362035 | AZ28: =AX28/AY28 -> 0.99978083 | BD28: 21.973157 | BE28: 0.060007742
A29: 136 | B29: 0.72329861 | C29: 0.72488426 | D29: 0.72351852 | F29: 75P7-3 | G29: 75 % Propylene | H29: 0.762 | I29: 101325 | J29: =0.75*42.08+0.25*28.0134 -> 38.56335 | K29: 42.08 | L29: 0.75 | M29: 68 | N29: 22 | O29: 134 | P29: 1.54 | Q29: 250 | R29: 431 | S29: =R29*Reference!$F$60+Reference!$F$61 -> 20.154749 | T29: 29 | U29: =T29*-Reference!$F$60 -> 6.5917305 | V29: =Reference!$L$22 -> 1743.4481 | W29: 2317.4 | X29: =Reference!$W$23 -> 0.049485 | Y29: =(20*10^-6)*(600/298)^(1.67) -> 6.4357835e-05 | Z29: =M29*Reference!$L$8 -> 32.703812 | AA29: =Z29*0.75 -> 24.527859 | AB29: =Z29*Reference!$L$23/(60*10^3) -> 0.8707943 | AC29: =AA29*Reference!$L$22/(60*1000) -> 0.7127175 | AD29: =N29*Reference!$F$10+Reference!$F$11 -> 14.766369 | AE29: =(Z29/(PI()/4*((H29/10)^2)*60)) -> 119.52185 | AF29: =AE29*2 -> 239.0437 | AG29: =AD29/(2*AE29) -> 0.061772675 | AH29: =(AE29/100)*Reference!$L$23*(H29/1000)/(Reference!$W$20) -> 29.050551 | AI29: =(AE29/100)*Reference!$L$23*(H29/1000)/(Reference!$P$26) -> 77.394995 | AJ29: =(AE29/100)*Reference!$L$23*(H29/1000)/(Reference!$P$23) -> 138.10911 | AK29: =AH29/Reference!$R$23 -> 378.34815 | AL29: =AI29/(Reference!$R$23) -> 1007.9758 | AM29: =AB29/(Reference!$R$23) -> 11.341038 | AN29: =S29/H29 -> 26.449802 | AO29: =0.00002*(AO$2/293)^1.67 -> 0.00030579718 | AQ29: =AE29/AD29 -> 8.0941937 | AR29: =(1/0.0557)*(H29/1000)^2*V29*(AE29/100)/6*((AE29/100)-(AD29/100)*0.75) -> 0.0039262475 | AS29: =0.75*AR29/(2*(AE29/100)-(AD29/100)) -> 0.0013129662 | AT29: =1000*(S29/1000)/(AD29/100)-(0.75*AR29/(AD29/100)^2)*LN(ABS(1+((AD29/100)*(S29/1000)/(0.75*AR29))*(1-((AD29/100)/(2*(AE29/100)))))) -> 136.40083 | AU29: =1/(AD29/100)*LN((4*AD29/100*(S29/1000+AS29)+3*AR29)/(4*AD29/100*AS29+3*AR29)) -> 4.5165377 | AV29: =1/(AD29/100)*LN((4*AD29/100*(S29/2000+AS29)+3*AR29)/(4*AD29/100*AS29+3*AR29)) -> 2.6280169 | AW29: =AU29-AV29 -> 1.8885208 | AX29: =1000*(S29/2000)/(AD29/100)-(0.75*AR29/(AD29/100)^2)*LN(ABS(1+((AD29/100)*(S29/2000)/(0.75*AR29))*(1-((AD29/100)/(2*(AE29/100)))))) -> 68.193039 | AY29: =AT29-AX29 -> 68.207786 | AZ29: =AX29/AY29 -> 0.99978379 | BD29: 20.154749 | BE29: 0.061772675
A30: 173 | B30: 0.52741898 | C30: 0.52868056 | D30: 0.52828704 | F30: 75P7-4 | G30: 75 % Propylene | H30: 0.762 | I30: 101325 | J30: =0.75*42.08+0.25*28.0134 -> 38.56335 | K30: 42.08 | L30: 0.75 | M30: 156 | N30: 47 | O30: 101 | P30: 3.72 | Q30: 250 | R30: 328 | S30: =R30*Reference!$B$78+Reference!$B$79 -> 43.976158 | T30: 25 | U30: =T30*-Reference!$B$78 -> 5.6474599 | V30: =Reference!$L$22 -> 1743.4481 | W30: 2317.4 | X30: =Reference!$W$23 -> 0.049485 | Y30: =(20*10^-6)*(600/298)^(1.67) -> 6.4357835e-05 | Z30: =M30*Reference!$L$8 -> 75.026393 | AA30: =Z30*0.75 -> 56.269795 | AB30: =Z30*Reference!$L$23/(60*10^3) -> 1.9977046 | AC30: =AA30*Reference!$L$22/(60*1000) -> 1.6350578 | AD30: =N30*Reference!$F$10+Reference!$F$11 -> 38.271753 | AE30: =(Z30/(PI()/4*((H30/10)^2)*60)) -> 274.19719 | AF30: =AE30*2 -> 548.39437 | AG30: =AD30/(2*AE30) -> 0.069788742 | AH30: =(AE30/100)*Reference!$L$23*(H30/1000)/(Reference!$W$20) -> 66.645382 | AI30: =(AE30/100)*Reference!$L$23*(H30/1000)/(Reference!$P$26) -> 177.55322 | AJ30: =(AE30/100)*Reference!$L$23*(H30/1000)/(Reference!$P$23) -> 316.83855 | AK30: =AH30/Reference!$R$23 -> 867.97518 | AL30: =AI30/(Reference!$R$23) -> 2312.4151 | AM30: =AB30/(Reference!$R$23) -> 26.017676 | AN30: =S30/H30 -> 57.711494 | AO30: =0.00002*(AO$2/293)^1.67 -> 0.00030579718 | AQ30: =AE30/AD30 -> 7.1644793 | AR30: =(1/0.0557)*(H30/1000)^2*V30*(AE30/100)/6*((AE30/100)-(AD30/100)*0.75) -> 0.020389909 | AS30: =0.75*AR30/(2*(AE30/100)-(AD30/100)) -> 0.0029977953 | AT30: =1000*(S30/1000)/(AD30/100)-(0.75*AR30/(AD30/100)^2)*LN(ABS(1+((AD30/100)*(S30/1000)/(0.75*AR30))*(1-((AD30/100)/(2*(AE30/100)))))) -> 114.8314 | AU30: =1/(AD30/100)*LN((4*AD30/100*(S30/1000+AS30)+3*AR30)/(4*AD30/100*AS30+3*AR30)) -> 1.8419854 | AV30: =1/(AD30/100)*LN((4*AD30/100*(S30/2000+AS30)+3*AR30)/(4*AD30/100*AS30+3*AR30)) -> 1.0800547 | AW30: =AU30-AV30 -> 0.76193068 | AX30: =1000*(S30/2000)/(AD30/100)-(0.75*AR30/(AD30/100)^2)*LN(ABS(1+((AD30/100)*(S30/2000)/(0.75*AR30))*(1-((AD30/100)/(2*(AE30/100)))))) -> 57.409344 | AY30: =AT30-AX30 -> 57.422055 | AZ30: =AX30/AY30 -> 0.99977863 | BD30: 43.976158 | BE30: 0.069788742
A31: 055 | B31: 0.40224537 | C31: 0.4033912 | D31: 0.40292824 | E31: 60E | F31: 50P16-1 | G31: 50 % Propylene | H31: 1.6002 | I31: 101325 | J31: =0.5*42.08+0.5*28.0134 -> 35.0467 | K31: 42.08 | L31: 0.5 | M31: 205 | N31: 49 | O31: 106 | P31: 3.78 | Q31: 250 | R31: 338 | S31: =R31*Reference!$J$42+Reference!$F$43 -> 41.728081 | T31: 26 | U31: =T31*-Reference!$J$42 -> 5.9973982 | V31: =Reference!$L$22 -> 1743.4481 | W31: 2288.3 | X31: =Reference!$W$24 -> 0.049136 | Y31: =(20*10^-6)*(600/298)^(1.67) -> 6.4357835e-05 | Z31: =M31*Reference!$L$9 -> 119.21986 | AA31: =Z31*0.5 -> 59.609929 | AB31: =Z31*Reference!$L$24/(60*10^3) -> 2.8846334 | AC31: =AA31*Reference!$L$22/(60*1000) -> 1.7321136 | AD31: =N31*Reference!$F$10+Reference!$F$11 -> 40.152184 | AE31: =(Z31/(PI()/4*((H31/10)^2)*60)) -> 98.800453 | AF31: =AE31*2 -> 197.60091 | AG31: =AD31/(2*AE31) -> 0.20319838 | AH31: =(AE31/100)*Reference!$L$24*(H31/1000)/(Reference!$W$24) -> 46.711808 | AI31: =(AE31/100)*Reference!$L$24*(H31/1000)/(Reference!$P$26) -> 122.08678 | AJ31: =(AE31/100)*Reference!$L$24*(H31/1000)/(Reference!$P$24) -> 181.00981 | AK31: =AH31/Reference!$R$24 -> 458.7179 | AL31: =AI31/(Reference!$R$24) -> 1198.9129 | AM31: =AB31/(Reference!$R$24) -> 28.32759 | AN31: =S31/H31 -> 26.076791 | AO31: =0.00002*(AO$2/293)^1.67 -> 0.00030579718 | AQ31: =AE31/AD31 -> 2.4606495 | AR31: =(1/0.0557)*(H31/1000)^2*V31*(AE31/100)/6*((AE31/100)-(AD31/100)*0.75) -> 0.0090652601 | AS31: =0.75*AR31/(2*(AE31/100)-(AD31/100)) -> 0.0043181964 | AT31: =1000*(S31/1000)/(AD31/100)-(0.75*AR31/(AD31/100)^2)*LN(ABS(1+((AD31/100)*(S31/1000)/(0.75*AR31))*(1-((AD31/100)/(2*(AE31/100)))))) -> 103.87899 | AU31: =1/(AD31/100)*LN((4*AD31/100*(S31/1000+AS31)+3*AR31)/(4*AD31/100*AS31+3*AR31)) -> 2.705692 | AV31: =1/(AD31/100)*LN((4*AD31/100*(S31/2000+AS31)+3*AR31)/(4*AD31/100*AS31+3*AR31)) -> 1.7035133 | AW31: =AU31-AV31 -> 1.0021787 | AX31: =1000*(S31/2000)/(AD31/100)-(0.75*AR31/(AD31/100)^2)*LN(ABS(1+((AD31/100)*(S31/2000)/(0.75*AR31))*(1-((AD31/100)/(2*(AE31/100)))))) -> 51.933559 | AY31: =AT31-AX31 -> 51.945435 | AZ31: =AX31/AY31 -> 0.99977138 | BD31: 41.728081 | BE31: 0.20319838 | BF31: 0.20319838 | BG31: =BF31*2 -> 0.40639676 | BH31: 41.728081 | BI31: 28.32759
